Workbook
Name SDK_CandidateMatrix: _xlfn.LAMBDA(_xlpm.board,_xlfn.MAKEARRAY(9,9,_xlfn.LAMBDA(_xlpm.r,_xlpm.c,SDK_Candidates(_xlpm.board,_xlpm.r,_xlpm.c))))
Name SDK_CoachHint: _xlfn.LAMBDA(_xlpm.board,SDK_CoachHintV2(_xlpm.board))
Name SDK_CoachTrace: _xlfn.LAMBDA(_xlpm.board,SDK_CoachTraceV2(_xlpm.board))
Name SDK_HasDeadEnd: _xlfn.LAMBDA(_xlpm.board,SDK_DeadEnd(_xlpm.board)<>"")
Name SDK_HasSolution: _xlfn.LAMBDA(_xlpm.board,IFERROR(_xlfn.LET(_xlpm.result,SDK_Solve(_xlpm.board),AND(ROWS(_xlpm.result)=9,COLUMNS(_xlpm.result)=9)),FALSE))
Name SDK_HintClaiming: _xlfn.LAMBDA(_xlpm.board,_xlfn.LET(_xlpm.a,SDK_HintClaimingRow(_xlpm.board),_xlpm.b,SDK_HintClaimingCol(_xlpm.board),IF(_xlpm.a<>"",_xlpm.a,_xlpm.b)))
Name SDK_HintPointing: _xlfn.LAMBDA(_xlpm.board,SDK_PointingHint(_xlpm.board))
Name SDK_HintPointingCol: _xlfn.LAMBDA(_xlpm.board,SDK_PointingColHint(_xlpm.board))
Name SDK_HintPointingRow: _xlfn.LAMBDA(_xlpm.board,SDK_PointingRowHint(_xlpm.board))
Name SDK_IsSolved: _xlfn.LAMBDA(_xlpm.board,_xlpm.solution,AND(_xlfn.TOCOL(_xlpm.board)=_xlfn.TOCOL(_xlpm.solution)))
Name SDK_PointingHint: _xlfn.LAMBDA(_xlpm.board,_xlfn.LET(_xlpm.rowHint,SDK_PointingRowHint(_xlpm.board),_xlpm.colHint,SDK_PointingColHint(_xlpm.board),IF(_xlpm.rowHint<>"",_xlpm.rowHint,_xlpm.colHint)))
Name SDK_Uniqueness: _xlfn.LAMBDA(_xlpm.board,IFERROR(_xlfn.LET(_xlpm.n,SDK_CountSolutions(_xlpm.board,2),CHOOSE(_xlpm.n+1,"NO SOLUTION","UNIQUE","MULTIPLE SOLUTIONS")),"SEARCH ERROR"))
Name SDKP_Chain: _xlfn.LAMBDA(_xlpm.board,_xlpm.lim,SDKP_ChainLoop(_xlpm.board,SDK_CandidateMatrix(_xlpm.board),0,_xlpm.lim,""))
Name SDKP_ClaimingCol: _xlfn.LAMBDA(_xlpm.inputCandidates,INDEX(SDKP_ClaimingColStep(_xlpm.inputCandidates),1,5))
Name SDKP_ClaimingRow: _xlfn.LAMBDA(_xlpm.inputCandidates,INDEX(SDKP_ClaimingRowStep(_xlpm.inputCandidates),1,5))
Name SDKP_HasProgress: _xlfn.LAMBDA(_xlpm.before,_xlpm.after,SUM(LEN(_xlpm.after&""))<SUM(LEN(_xlpm.before&"")))
Name SDKP_NakedPairBox: _xlfn.LAMBDA(_xlpm.inputCandidates,INDEX(SDKP_NakedPairBoxStep(_xlpm.inputCandidates),1,5))
Name SDKP_NakedPairCol: _xlfn.LAMBDA(_xlpm.inputCandidates,INDEX(SDKP_NakedPairColStep(_xlpm.inputCandidates),1,5))
Name SDKP_NakedPairRow: _xlfn.LAMBDA(_xlpm.inputCandidates,INDEX(SDKP_NakedPairRowStep(_xlpm.inputCandidates),1,5))
Name SDKP_PointingCol: _xlfn.LAMBDA(_xlpm.inputCandidates,INDEX(SDKP_PointingColStep(_xlpm.inputCandidates),1,5))
Name SDKP_PointingRow: _xlfn.LAMBDA(_xlpm.inputCandidates,INDEX(SDKP_PointingRowStep(_xlpm.inputCandidates),1,5))

Sheet README
A1: EXCEL SUDOKU
A2: Five independent, formula-driven Sudoku games built with ordinary cells, dynamic arrays and named LAMBDA functions — no VBA or macros at runtime.
A4: START PLAYING
A5: =HYPERLINK("#'01 Easy'!B1","01 EASY") -> 01 EASY | D5: 30 givens | F5: Learn the interface and basic solving flow.
A6: =HYPERLINK("#'02 Medium'!B1","02 MEDIUM") -> 02 MEDIUM | D6: 36 givens | F6: More constrained, but less immediately obvious.
A7: =HYPERLINK("#'03 Hard'!B1","03 HARD") -> 03 HARD | D7: 28 givens | F7: Requires more candidate reading and patience.
A8: =HYPERLINK("#'04 Expert'!B1","04 EXPERT") -> 04 EXPERT | D8: 27 givens | F8: Designed for multi-step logical progress.
A9: =HYPERLINK("#'05 Master'!B1","05 MASTER") -> 05 MASTER | D9: 23 givens | F9: The sparsest and most demanding published page.
A10: WHY THIS IS INTERESTING
A11: A stateful puzzle interface, live candidates, logical coaching, recursive search and automated tests — implemented entirely with ordinary cells and modern Excel formulas.
A12: HOW TO PLAY
A13: 01 ENTER ANSWERS
A14: Select a green-underlined center and type 1–9. Delete clears; gray clue centers reject edits.
A15: 02 READ LIVE CANDIDATES
A16: Small surrounding digits are formula-generated legal candidates and update after every entry.
A17: 03 ASK THE COACH
A18: Off = normal · Hint = one step · Trace = explanation · Verify = global search and may take several seconds. Return Verify to Off afterward.
A20: VISUAL LANGUAGE
A21: GRAY CENTER — Fixed clue supplied by the puzzle.
A22: WHITE + GREEN LINE — Editable answer center.
... A37: WORKBOOK MAP
A38: Game pages | D38: 01 Easy through 05 Master
A39: Formula Reference | D39: =HYPERLINK("#'Formula Reference'!A1","Human-readable formula architecture") -> Human-readable formula architecture
A40: Hidden engines | D40: One isolated calculation layer per puzzle
A41: _Tests | D41: Automated development regression suite
A42: Requirements | D42: Microsoft Excel 365 Desktop with dynamic arrays and LAMBDA
A44: BUILD STATUS
A45: Tests | D45: =COUNTIF(_Tests!$E:$E,"PASS")&" checks passing · "&COUNTIF(_Tests!$E:$E,"SKIP")&" on demand" -> 131 checks passing · 18 on demand
A46: Puzzles | D46: 5 / 5 UNIQUE
A48: PROJECT STATUS
A49: Five fixed, book-style game pages demonstrate Excel as a formula-driven interactive application. All gameplay remains inside ordinary worksheet cells.
A50: Unique puzzles — Bounded search confirms all five published puzzles have exactly one solution.
A51: Current boundary — Formulas cannot receive click events or imperatively write another cell, so the editable answer cell remains visible inside each rendered square.
A53: RELEASE INFORMATION
A54: Version | D54: 1.0.0
A55: Build date | D55: =DATE(2026,7,27) -> 46230
A56: Supported | D56: Microsoft Excel 365 Desktop
A57: Unverified | D57: Excel 2024 · Excel for Web (unverified)
A58: Reset | D58: Delete entries in green-underlined centers, or reopen a clean copy of the workbook.
A59: Verify performance | D59: Global verification may take several seconds; Master can take substantially longer on slower computers.

Sheet 01 Easy
B1: EXCEL SUDOKU · EASY 01
B2: Difficulty: Easy · 30 givens · Independent formula engine · Enter answers directly in the board
B4: {=_xlfn.LET(_xlpm.r,QUOTIENT(ROW()-4,3)+1,_xlpm.c,QUOTIENT(COLUMN()-2,4)+1,_xlpm.live,INDEX(_Engine!$B$3:$J$11,_xlpm.r,_xlpm.c),_xlpm.cand,INDEX(_Engine!$B$15:$J$23,_xlpm.r,_xlpm.c),_xlpm.bad,INDEX(_Engine!$B$51:$J$59,_xlpm.r,_xlpm.c),_xlpm.note,INDEX($B$4:$AK$30,3*_xlpm.r,4*_xlpm.c),_xlpm.coord,"R"&_xlpm.r&"C"&_xlpm.c,_xlpm.role,SDK_CoordRole(_Engine!$B$88,_xlpm.coord),_xlpm.mark,IF(_xlpm.bad,"✖",IF($AS$11="Off","",IF(_xlpm.role="TARGET","▼",IF(_xlpm.role="SOURCE","●","")))),_xlpm.digit,IF(_xlpm.live<>"","",SDK_RenderDigit("Auto",_xlpm.note,_xlpm.cand,1)),_xlfn.TEXTJOIN(" ",TRUE,_xlpm.mark,_xlpm.digit))} | C4: {=IF(_Engine!B3<>"","",SDK_RenderDigit("Auto",$E$6,_Engine!B15,2))} | D4: {=IF(_Engine!B3<>"","",SDK_RenderDigit("Auto",$E$6,_Engine!B15,3))} | F4: {=_xlfn.LET(_xlpm.r,QUOTIENT(ROW()-4,3)+1,_xlpm.c,QUOTIENT(COLUMN()-2,4)+1,_xlpm.live,INDEX(_Engine!$B$3:$J$11,_xlpm.r,_xlpm.c),_xlpm.cand,INDEX(_Engine!$B$15:$J$23,_xlpm.r,_xlpm.c),_xlpm.bad,INDEX(_Engine!$B$51:$J$59,_xlpm.r,_xlpm.c),_xlpm.note,INDEX($B$4:$AK$30,3*_xlpm.r,4*_xlpm.c),_xlpm.coord,"R"&_xlpm.r&"C"&_xlpm.c,_xlpm.role,SDK_CoordRole(_Engine!$B$88,_xlpm.coord),_xlpm.mark,IF(_xlpm.bad,"✖",IF($AS$11="Off","",IF(_xlpm.role="TARGET","▼",IF(_xlpm.role="SOURCE","●","")))),_xlpm.digit,IF(_xlpm.live<>"","",SDK_RenderDigit("Auto",_xlpm.note,_xlpm.cand,1)),_xlfn.TEXTJOIN(" ",TRUE,_xlpm.mark,_xlpm.digit))} | G4: {=IF(_Engine!C3<>"","",SDK_RenderDigit("Auto",$I$6,_Engine!C15,2))} | H4: {=IF(_Engine!C3<>"","",SDK_RenderDigit("Auto",$I$6,_Engine!C15,3))} | J4: {=_xlfn.LET(_xlpm.r,QUOTIENT(ROW()-4,3)+1,_xlpm.c,QUOTIENT(COLUMN()-2,4)+1,_xlpm.live,INDEX(_Engine!$B$3:$J$11,_xlpm.r,_xlpm.c),_xlpm.cand,INDEX(_Engine!$B$15:$J$23,_xlpm.r,_xlpm.c),_xlpm.bad,INDEX(_Engine!$B$51:$J$59,_xlpm.r,_xlpm.c),_xlpm.note,INDEX($B$4:$AK$30,3*_xlpm.r,4*_xlpm.c),_xlpm.coord,"R"&_xlpm.r&"C"&_xlpm.c,_xlpm.role,SDK_CoordRole(_Engine!$B$88,_xlpm.coord),_xlpm.mark,IF(_xlpm.bad,"✖",IF($AS$11="Off","",IF(_xlpm.role="TARGET","▼",IF(_xlpm.role="SOURCE","●","")))),_xlpm.digit,IF(_xlpm.live<>"","",SDK_RenderDigit("Auto",_xlpm.note,_xlpm.cand,1)),_xlfn.TEXTJOIN(" ",TRUE,_xlpm.mark,_xlpm.digit))} -> 1 | K4: {=IF(_Engine!D3<>"","",SDK_RenderDigit("Auto",$M$6,_Engine!D15,2))} -> 2 | L4: {=IF(_Engine!D3<>"","",SDK_RenderDigit("Auto",$M$6,_Engine!D15,3))} | N4: {=_xlfn.LET(_xlpm.r,QUOTIENT(ROW()-4,3)+1,_xlpm.c,QUOTIENT(COLUMN()-2,4)+1,_xlpm.live,INDEX(_Engine!$B$3:$J$11,_xlpm.r,_xlpm.c),_xlpm.cand,INDEX(_Engine!$B$15:$J$23,_xlpm.r,_xlpm.c),_xlpm.bad,INDEX(_Engine!$B$51:$J$59,_xlpm.r,_xlpm.c),_xlpm.note,INDEX($B$4:$AK$30,3*_xlpm.r,4*_xlpm.c),_xlpm.coord,"R"&_xlpm.r&"C"&_xlpm.c,_xlpm.role,SDK_CoordRole(_Engine!$B$88,_xlpm.coord),_xlpm.mark,IF(_xlpm.bad,"✖",IF($AS$11="Off","",IF(_xlpm.role="TARGET","▼",IF(_xlpm.role="SOURCE","●","")))),_xlpm.digit,IF(_xlpm.live<>"","",SDK_RenderDigit("Auto",_xlpm.note,_xlpm.cand,1)),_xlfn.TEXTJOIN(" ",TRUE,_xlpm.mark,_xlpm.digit))} | O4: {=IF(_Engine!E3<>"","",SDK_RenderDigit("Auto",$Q$6,_Engine!E15,2))} -> 2 | P4: {=IF(_Engine!E3<>"","",SDK_RenderDigit("Auto",$Q$6,_Engine!E15,3))} | R4: {=_xlfn.LET(_xlpm.r,QUOTIENT(ROW()-4,3)+1,_xlpm.c,QUOTIENT(COLUMN()-2,4)+1,_xlpm.live,INDEX(_Engine!$B$3:$J$11,_xlpm.r,_xlpm.c),_xlpm.cand,INDEX(_Engine!$B$15:$J$23,_xlpm.r,_xlpm.c),_xlpm.bad,INDEX(_Engine!$B$51:$J$59,_xlpm.r,_xlpm.c),_xlpm.note,INDEX($B$4:$AK$30,3*_xlpm.r,4*_xlpm.c),_xlpm.coord,"R"&_xlpm.r&"C"&_xlpm.c,_xlpm.role,SDK_CoordRole(_Engine!$B$88,_xlpm.coord),_xlpm.mark,IF(_xlpm.bad,"✖",IF($AS$11="Off","",IF(_xlpm.role="TARGET","▼",IF(_xlpm.role="SOURCE","●","")))),_xlpm.digit,IF(_xlpm.live<>"","",SDK_RenderDigit("Auto",_xlpm.note,_xlpm.cand,1)),_xlfn.TEXTJOIN(" ",TRUE,_xlpm.mark,_xlpm.digit))} | S4: {=IF(_Engine!F3<>"","",SDK_RenderDigit("Auto",$U$6,_Engine!F15,2))} | T4: {=IF(_Engine!F3<>"","",SDK_RenderDigit("Auto",$U$6,_Engine!F15,3))} | V4: {=_xlfn.LET(_xlpm.r,QUOTIENT(ROW()-4,3)+1,_xlpm.c,QUOTIENT(COLUMN()-2,4)+1,_xlpm.live,INDEX(_Engine!$B$3:$J$11,_xlpm.r,_xlpm.c),_xlpm.cand,INDEX(_Engine!$B$15:$J$23,_xlpm.r,_xlpm.c),_xlpm.bad,INDEX(_Engine!$B$51:$J$59,_xlpm.r,_xlpm.c),_xlpm.note,INDEX($B$4:$AK$30,3*_xlpm.r,4*_xlpm.c),_xlpm.coord,"R"&_xlpm.r&"C"&_xlpm.c,_xlpm.role,SDK_CoordRole(_Engine!$B$88,_xlpm.coord),_xlpm.mark,IF(_xlpm.bad,"✖",IF($AS$11="Off","",IF(_xlpm.role="TARGET","▼",IF(_xlpm.role="SOURCE","●","")))),_xlpm.digit,IF(_xlpm.live<>"","",SDK_RenderDigit("Auto",_xlpm.note,_xlpm.cand,1)),_xlfn.TEXTJOIN(" ",TRUE,_xlpm.mark,_xlpm.digit))} | W4: {=IF(_Engine!G3<>"","",SDK_RenderDigit("Auto",$Y$6,_Engine!G15,2))} -> 2 | X4: {=IF(_Engine!G3<>"","",SDK_RenderDigit("Auto",$Y$6,_Engine!G15,3))} | Z4: {=_xlfn.LET(_xlpm.r,QUOTIENT(ROW()-4,3)+1,_xlpm.c,QUOTIENT(COLUMN()-2,4)+1,_xlpm.live,INDEX(_Engine!$B$3:$J$11,_xlpm.r,_xlpm.c),_xlpm.cand,INDEX(_Engine!$B$15:$J$23,_xlpm.r,_xlpm.c),_xlpm.bad,INDEX(_Engine!$B$51:$J$59,_xlpm.r,_xlpm.c),_xlpm.note,INDEX($B$4:$AK$30,3*_xlpm.r,4*_xlpm.c),_xlpm.coord,"R"&_xlpm.r&"C"&_xlpm.c,_xlpm.role,SDK_CoordRole(_Engine!$B$88,_xlpm.coord),_xlpm.mark,IF(_xlpm.bad,"✖",IF($AS$11="Off","",IF(_xlpm.role="TARGET","▼",IF(_xlpm.role="SOURCE","●","")))),_xlpm.digit,IF(_xlpm.live<>"","",SDK_RenderDigit("Auto",_xlpm.note,_xlpm.cand,1)),_xlfn.TEXTJOIN(" ",TRUE,_xlpm.mark,_xlpm.digit))} -> 1 | AA4: {=IF(_Engine!H3<>"","",SDK_RenderDigit("Auto",$AC$6,_Engine!H15,2))} | AB4: {=IF(_Engine!H3<>"","",SDK_RenderDigit("Auto",$AC$6,_Engine!H15,3))} | AD4: {=_xlfn.LET(_xlpm.r,QUOTIENT(ROW()-4,3)+1,_xlpm.c,QUOTIENT(COLUMN()-2,4)+1,_xlpm.live,INDEX(_Engine!$B$3:$J$11,_xlpm.r,_xlpm.c),_xlpm.cand,INDEX(_Engine!$B$15:$J$23,_xlpm.r,_xlpm.c),_xlpm.bad,INDEX(_Engine!$B$51:$J$59,_xlpm.r,_xlpm.c),_xlpm.note,INDEX($B$4:$AK$30,3*_xlpm.r,4*_xlpm.c),_xlpm.coord,"R"&_xlpm.r&"C"&_xlpm.c,_xlpm.role,SDK_CoordRole(_Engine!$B$88,_xlpm.coord),_xlpm.mark,IF(_xlpm.bad,"✖",IF($AS$11="Off","",IF(_xlpm.role="TARGET","▼",IF(_xlpm.role="SOURCE","●","")))),_xlpm.digit,IF(_xlpm.live<>"","",SDK_RenderDigit("Auto",_xlpm.note,_xlpm.cand,1)),_xlfn.TEXTJOIN(" ",TRUE,_xlpm.mark,_xlpm.digit))} -> 1 | AE4: {=IF(_Engine!I3<>"","",SDK_RenderDigit("Auto",$AG$6,_Engine!I15,2))} -> 2 | AF4: {=IF(_Engine!I3<>"","",SDK_RenderDigit("Auto",$AG$6,_Engine!I15,3))} | AH4: {=_xlfn.LET(_xlpm.r,QUOTIENT(ROW()-4,3)+1,_xlpm.c,QUOTIENT(COLUMN()-2,4)+1,_xlpm.live,INDEX(_Engine!$B$3:$J$11,_xlpm.r,_xlpm.c),_xlpm.cand,INDEX(_Engine!$B$15:$J$23,_xlpm.r,_xlpm.c),_xlpm.bad,INDEX(_Engine!$B$51:$J$59,_xlpm.r,_xlpm.c),_xlpm.note,INDEX($B$4:$AK$30,3*_xlpm.r,4*_xlpm.c),_xlpm.coord,"R"&_xlpm.r&"C"&_xlpm.c,_xlpm.role,SDK_CoordRole(_Engine!$B$88,_xlpm.coord),_xlpm.mark,IF(_xlpm.bad,"✖",IF($AS$11="Off","",IF(_xlpm.role="TARGET","▼",IF(_xlpm.role="SOURCE","●","")))),_xlpm.digit,IF(_xlpm.live<>"","",SDK_RenderDigit("Auto",_xlpm.note,_xlpm.cand,1)),_xlfn.TEXTJOIN(" ",TRUE,_xlpm.mark,_xlpm.digit))} | AI4: {=IF(_Engine!J3<>"","",SDK_RenderDigit("Auto",$AK$6,_Engine!J15,2))} -> 2 | AJ4: {=IF(_Engine!J3<>"","",SDK_RenderDigit("Auto",$AK$6,_Engine!J15,3))} | AM4: GAME STATUS
B5: {=_xlfn.LET(_xlpm.r,QUOTIENT(ROW()-5,3)+1,_xlpm.c,QUOTIENT(COLUMN()-2,4)+1,_xlpm.live,INDEX(_Engine!$B$3:$J$11,_xlpm.r,_xlpm.c),_xlpm.cand,INDEX(_Engine!$B$15:$J$23,_xlpm.r,_xlpm.c),_xlpm.note,INDEX($B$4:$AK$30,3*_xlpm.r,4*_xlpm.c),IF(_xlpm.live<>"","",_xlfn.TEXTJOIN("·",TRUE,SDK_RenderDigit("Auto",_xlpm.note,_xlpm.cand,4),SDK_RenderDigit("Auto",_xlpm.note,_xlpm.cand,5))))} | C5: =_Engine!B27 -> 5 | D5: {=IF(_Engine!B3<>"","",SDK_RenderDigit("Auto",$E$6,_Engine!B15,6))} | F5: {=_xlfn.LET(_xlpm.r,QUOTIENT(ROW()-5,3)+1,_xlpm.c,QUOTIENT(COLUMN()-2,4)+1,_xlpm.live,INDEX(_Engine!$B$3:$J$11,_xlpm.r,_xlpm.c),_xlpm.cand,INDEX(_Engine!$B$15:$J$23,_xlpm.r,_xlpm.c),_xlpm.note,INDEX($B$4:$AK$30,3*_xlpm.r,4*_xlpm.c),IF(_xlpm.live<>"","",_xlfn.TEXTJOIN("·",TRUE,SDK_RenderDigit("Auto",_xlpm.note,_xlpm.cand,4),SDK_RenderDigit("Auto",_xlpm.note,_xlpm.cand,5))))} | G5: =_Engine!C27 -> 3 | H5: {=IF(_Engine!C3<>"","",SDK_RenderDigit("Auto",$I$6,_Engine!C15,6))} | J5: {=_xlfn.LET(_xlpm.r,QUOTIENT(ROW()-5,3)+1,_xlpm.c,QUOTIENT(COLUMN()-2,4)+1,_xlpm.live,INDEX(_Engine!$B$3:$J$11,_xlpm.r,_xlpm.c),_xlpm.cand,INDEX(_Engine!$B$15:$J$23,_xlpm.r,_xlpm.c),_xlpm.note,INDEX($B$4:$AK$30,3*_xlpm.r,4*_xlpm.c),IF(_xlpm.live<>"","",_xlfn.TEXTJOIN("·",TRUE,SDK_RenderDigit("Auto",_xlpm.note,_xlpm.cand,4),SDK_RenderDigit("Auto",_xlpm.note,_xlpm.cand,5))))} -> 4 | L5: {=IF(_Engine!D3<>"","",SDK_RenderDigit("Auto",$M$6,_Engine!D15,6))} | N5: {=_xlfn.LET(_xlpm.r,QUOTIENT(ROW()-5,3)+1,_xlpm.c,QUOTIENT(COLUMN()-2,4)+1,_xlpm.live,INDEX(_Engine!$B$3:$J$11,_xlpm.r,_xlpm.c),_xlpm.cand,INDEX(_Engine!$B$15:$J$23,_xlpm.r,_xlpm.c),_xlpm.note,INDEX($B$4:$AK$30,3*_xlpm.r,4*_xlpm.c),IF(_xlpm.live<>"","",_xlfn.TEXTJOIN("·",TRUE,SDK_RenderDigit("Auto",_xlpm.note,_xlpm.cand,4),SDK_RenderDigit("Auto",_xlpm.note,_xlpm.cand,5))))} | P5: {=IF(_Engine!E3<>"","",SDK_RenderDigit("Auto",$Q$6,_Engine!E15,6))} -> 6 | R5: {=_xlfn.LET(_xlpm.r,QUOTIENT(ROW()-5,3)+1,_xlpm.c,QUOTIENT(COLUMN()-2,4)+1,_xlpm.live,INDEX(_Engine!$B$3:$J$11,_xlpm.r,_xlpm.c),_xlpm.cand,INDEX(_Engine!$B$15:$J$23,_xlpm.r,_xlpm.c),_xlpm.note,INDEX($B$4:$AK$30,3*_xlpm.r,4*_xlpm.c),IF(_xlpm.live<>"","",_xlfn.TEXTJOIN("·",TRUE,SDK_RenderDigit("Auto",_xlpm.note,_xlpm.cand,4),SDK_RenderDigit("Auto",_xlpm.note,_xlpm.cand,5))))} | S5: =_Engine!F27 -> 7 | T5: {=IF(_Engine!F3<>"","",SDK_RenderDigit("Auto",$U$6,_Engine!F15,6))} | V5: {=_xlfn.LET(_xlpm.r,QUOTIENT(ROW()-5,3)+1,_xlpm.c,QUOTIENT(COLUMN()-2,4)+1,_xlpm.live,INDEX(_Engine!$B$3:$J$11,_xlpm.r,_xlpm.c),_xlpm.cand,INDEX(_Engine!$B$15:$J$23,_xlpm.r,_xlpm.c),_xlpm.note,INDEX($B$4:$AK$30,3*_xlpm.r,4*_xlpm.c),IF(_xlpm.live<>"","",_xlfn.TEXTJOIN("·",TRUE,SDK_RenderDigit("Auto",_xlpm.note,_xlpm.cand,4),SDK_RenderDigit("Auto",_xlpm.note,_xlpm.cand,5))))} -> 4 | X5: {=IF(_Engine!G3<>"","",SDK_RenderDigit("Auto",$Y$6,_Engine!G15,6))} -> 6 | Z5: {=_xlfn.LET(_xlpm.r,QUOTIENT(ROW()-5,3)+1,_xlpm.c,QUOTIENT(COLUMN()-2,4)+1,_xlpm.live,INDEX(_Engine!$B$3:$J$11,_xlpm.r,_xlpm.c),_xlpm.cand,INDEX(_Engine!$B$15:$J$23,_xlpm.r,_xlpm.c),_xlpm.note,INDEX($B$4:$AK$30,3*_xlpm.r,4*_xlpm.c),IF(_xlpm.live<>"","",_xlfn.TEXTJOIN("·",TRUE,SDK_RenderDigit("Auto",_xlpm.note,_xlpm.cand,4),SDK_RenderDigit("Auto",_xlpm.note,_xlpm.cand,5))))} -> 4 | AB5: {=IF(_Engine!H3<>"","",SDK_RenderDigit("Auto",$AC$6,_Engine!H15,6))} | AD5: {=_xlfn.LET(_xlpm.r,QUOTIENT(ROW()-5,3)+1,_xlpm.c,QUOTIENT(COLUMN()-2,4)+1,_xlpm.live,INDEX(_Engine!$B$3:$J$11,_xlpm.r,_xlpm.c),_xlpm.cand,INDEX(_Engine!$B$15:$J$23,_xlpm.r,_xlpm.c),_xlpm.note,INDEX($B$4:$AK$30,3*_xlpm.r,4*_xlpm.c),IF(_xlpm.live<>"","",_xlfn.TEXTJOIN("·",TRUE,SDK_RenderDigit("Auto",_xlpm.note,_xlpm.cand,4),SDK_RenderDigit("Auto",_xlpm.note,_xlpm.cand,5))))} -> 4 | AF5: {=IF(_Engine!I3<>"","",SDK_RenderDigit("Auto",$AG$6,_Engine!I15,6))} | AH5: {=_xlfn.LET(_xlpm.r,QUOTIENT(ROW()-5,3)+1,_xlpm.c,QUOTIENT(COLUMN()-2,4)+1,_xlpm.live,INDEX(_Engine!$B$3:$J$11,_xlpm.r,_xlpm.c),_xlpm.cand,INDEX(_Engine!$B$15:$J$23,_xlpm.r,_xlpm.c),_xlpm.note,INDEX($B$4:$AK$30,3*_xlpm.r,4*_xlpm.c),IF(_xlpm.live<>"","",_xlfn.TEXTJOIN("·",TRUE,SDK_RenderDigit("Auto",_xlpm.note,_xlpm.cand,4),SDK_RenderDigit("Auto",_xlpm.note,_xlpm.cand,5))))} -> 4 | AJ5: {=IF(_Engine!J3<>"","",SDK_RenderDigit("Auto",$AK$6,_Engine!J15,6))} | AM5: {=_xlfn.LET(_xlpm.conf,COUNTIF(_Engine!$B$51:$J$59,TRUE),_xlpm.dead,_Engine!$B$99,_xlpm.state,IF(SDK_IsSolved(_Engine!$B$3:$J$11,_Engine!$B$39:$J$47),"SOLVED",IF(_xlpm.conf>0,"CONFLICT",IF(_xlpm.dead,"DEAD END",IF(COUNT(_Engine!$B$3:$J$11)=81,"CHECK ERRORS","IN PROGRESS")))),_xlpm.state&" · "&(COUNT(_Engine!$B$3:$J$11)-COUNT(_Engine!$B$27:$J$35))&" answers entered")} -> IN PROGRESS · 0 answers entered
B6: {=IF(_Engine!B3<>"","",SDK_RenderDigit("Auto",$E$6,_Engine!B15,7))} | C6: {=IF(_Engine!B3<>"","",SDK_RenderDigit("Auto",$E$6,_Engine!B15,8))} | D6: {=IF(_Engine!B3<>"","",SDK_RenderDigit("Auto",$E$6,_Engine!B15,9))} | E6: ="" | F6: {=IF(_Engine!C3<>"","",SDK_RenderDigit("Auto",$I$6,_Engine!C15,7))} | G6: {=IF(_Engine!C3<>"","",SDK_RenderDigit("Auto",$I$6,_Engine!C15,8))} | H6: {=IF(_Engine!C3<>"","",SDK_RenderDigit("Auto",$I$6,_Engine!C15,9))} | I6: ="" | J6: {=IF(_Engine!D3<>"","",SDK_RenderDigit("Auto",$M$6,_Engine!D15,7))} | K6: {=IF(_Engine!D3<>"","",SDK_RenderDigit("Auto",$M$6,_Engine!D15,8))} | L6: {=IF(_Engine!D3<>"","",SDK_RenderDigit("Auto",$M$6,_Engine!D15,9))} | M6: ="" | N6: {=IF(_Engine!E3<>"","",SDK_RenderDigit("Auto",$Q$6,_Engine!E15,7))} | O6: {=IF(_Engine!E3<>"","",SDK_RenderDigit("Auto",$Q$6,_Engine!E15,8))} | P6: {=IF(_Engine!E3<>"","",SDK_RenderDigit("Auto",$Q$6,_Engine!E15,9))} | Q6: ="" | R6: {=IF(_Engine!F3<>"","",SDK_RenderDigit("Auto",$U$6,_Engine!F15,7))} | S6: {=IF(_Engine!F3<>"","",SDK_RenderDigit("Auto",$U$6,_Engine!F15,8))} | T6: {=IF(_Engine!F3<>"","",SDK_RenderDigit("Auto",$U$6,_Engine!F15,9))} | U6: ="" | V6: {=IF(_Engine!G3<>"","",SDK_RenderDigit("Auto",$Y$6,_Engine!G15,7))} | W6: {=IF(_Engine!G3<>"","",SDK_RenderDigit("Auto",$Y$6,_Engine!G15,8))} -> 8 | X6: {=IF(_Engine!G3<>"","",SDK_RenderDigit("Auto",$Y$6,_Engine!G15,9))} | Y6: ="" | Z6: {=IF(_Engine!H3<>"","",SDK_RenderDigit("Auto",$AC$6,_Engine!H15,7))} | AA6: {=IF(_Engine!H3<>"","",SDK_RenderDigit("Auto",$AC$6,_Engine!H15,8))} -> 8 | AB6: {=IF(_Engine!H3<>"","",SDK_RenderDigit("Auto",$AC$6,_Engine!H15,9))} -> 9 | AC6: ="" | AD6: {=IF(_Engine!I3<>"","",SDK_RenderDigit("Auto",$AG$6,_Engine!I15,7))} | AE6: {=IF(_Engine!I3<>"","",SDK_RenderDigit("Auto",$AG$6,_Engine!I15,8))} | AF6: {=IF(_Engine!I3<>"","",SDK_RenderDigit("Auto",$AG$6,_Engine!I15,9))} -> 9 | AG6: ="" | AH6: {=IF(_Engine!J3<>"","",SDK_RenderDigit("Auto",$AK$6,_Engine!J15,7))} | AI6: {=IF(_Engine!J3<>"","",SDK_RenderDigit("Auto",$AK$6,_Engine!J15,8))} -> 8 | AJ6: {=IF(_Engine!J3<>"","",SDK_RenderDigit("Auto",$AK$6,_Engine!J15,9))} | AK6: =""
B7: {=_xlfn.LET(_xlpm.r,QUOTIENT(ROW()-4,3)+1,_xlpm.c,QUOTIENT(COLUMN()-2,4)+1,_xlpm.live,INDEX(_Engine!$B$3:$J$11,_xlpm.r,_xlpm.c),_xlpm.cand,INDEX(_Engine!$B$15:$J$23,_xlpm.r,_xlpm.c),_xlpm.bad,INDEX(_Engine!$B$51:$J$59,_xlpm.r,_xlpm.c),_xlpm.note,INDEX($B$4:$AK$30,3*_xlpm.r,4*_xlpm.c),_xlpm.coord,"R"&_xlpm.r&"C"&_xlpm.c,_xlpm.role,SDK_CoordRole(_Engine!$B$88,_xlpm.coord),_xlpm.mark,IF(_xlpm.bad,"✖",IF($AS$11="Off","",IF(_xlpm.role="TARGET","▼",IF(_xlpm.role="SOURCE","●","")))),_xlpm.digit,IF(_xlpm.live<>"","",SDK_RenderDigit("Auto",_xlpm.note,_xlpm.cand,1)),_xlfn.TEXTJOIN(" ",TRUE,_xlpm.mark,_xlpm.digit))} | C7: {=IF(_Engine!B4<>"","",SDK_RenderDigit("Auto",$E$9,_Engine!B16,2))} | D7: {=IF(_Engine!B4<>"","",SDK_RenderDigit("Auto",$E$9,_Engine!B16,3))} | F7: {=_xlfn.LET(_xlpm.r,QUOTIENT(ROW()-4,3)+1,_xlpm.c,QUOTIENT(COLUMN()-2,4)+1,_xlpm.live,INDEX(_Engine!$B$3:$J$11,_xlpm.r,_xlpm.c),_xlpm.cand,INDEX(_Engine!$B$15:$J$23,_xlpm.r,_xlpm.c),_xlpm.bad,INDEX(_Engine!$B$51:$J$59,_xlpm.r,_xlpm.c),_xlpm.note,INDEX($B$4:$AK$30,3*_xlpm.r,4*_xlpm.c),_xlpm.coord,"R"&_xlpm.r&"C"&_xlpm.c,_xlpm.role,SDK_CoordRole(_Engine!$B$88,_xlpm.coord),_xlpm.mark,IF(_xlpm.bad,"✖",IF($AS$11="Off","",IF(_xlpm.role="TARGET","▼",IF(_xlpm.role="SOURCE","●","")))),_xlpm.digit,IF(_xlpm.live<>"","",SDK_RenderDigit("Auto",_xlpm.note,_xlpm.cand,1)),_xlfn.TEXTJOIN(" ",TRUE,_xlpm.mark,_xlpm.digit))} | G7: {=IF(_Engine!C4<>"","",SDK_RenderDigit("Auto",$I$9,_Engine!C16,2))} -> 2 | H7: {=IF(_Engine!C4<>"","",SDK_RenderDigit("Auto",$I$9,_Engine!C16,3))} | J7: {=_xlfn.LET(_xlpm.r,QUOTIENT(ROW()-4,3)+1,_xlpm.c,QUOTIENT(COLUMN()-2,4)+1,_xlpm.live,INDEX(_Engine!$B$3:$J$11,_xlpm.r,_xlpm.c),_xlpm.cand,INDEX(_Engine!$B$15:$J$23,_xlpm.r,_xlpm.c),_xlpm.bad,INDEX(_Engine!$B$51:$J$59,_xlpm.r,_xlpm.c),_xlpm.note,INDEX($B$4:$AK$30,3*_xlpm.r,4*_xlpm.c),_xlpm.coord,"R"&_xlpm.r&"C"&_xlpm.c,_xlpm.role,SDK_CoordRole(_Engine!$B$88,_xlpm.coord),_xlpm.mark,IF(_xlpm.bad,"✖",IF($AS$11="Off","",IF(_xlpm.role="TARGET","▼",IF(_xlpm.role="SOURCE","●","")))),_xlpm.digit,IF(_xlpm.live<>"","",SDK_RenderDigit("Auto",_xlpm.note,_xlpm.cand,1)),_xlfn.TEXTJOIN(" ",TRUE,_xlpm.mark,_xlpm.digit))} | K7: {=IF(_Engine!D4<>"","",SDK_RenderDigit("Auto",$M$9,_Engine!D16,2))} -> 2 | L7: {=IF(_Engine!D4<>"","",SDK_RenderDigit("Auto",$M$9,_Engine!D16,3))} | N7: {=_xlfn.LET(_xlpm.r,QUOTIENT(ROW()-4,3)+1,_xlpm.c,QUOTIENT(COLUMN()-2,4)+1,_xlpm.live,INDEX(_Engine!$B$3:$J$11,_xlpm.r,_xlpm.c),_xlpm.cand,INDEX(_Engine!$B$15:$J$23,_xlpm.r,_xlpm.c),_xlpm.bad,INDEX(_Engine!$B$51:$J$59,_xlpm.r,_xlpm.c),_xlpm.note,INDEX($B$4:$AK$30,3*_xlpm.r,4*_xlpm.c),_xlpm.coord,"R"&_xlpm.r&"C"&_xlpm.c,_xlpm.role,SDK_CoordRole(_Engine!$B$88,_xlpm.coord),_xlpm.mark,IF(_xlpm.bad,"✖",IF($AS$11="Off","",IF(_xlpm.role="TARGET","▼",IF(_xlpm.role="SOURCE","●","")))),_xlpm.digit,IF(_xlpm.live<>"","",SDK_RenderDigit("Auto",_xlpm.note,_xlpm.cand,1)),_xlfn.TEXTJOIN(" ",TRUE,_xlpm.mark,_xlpm.digit))} | O7: {=IF(_Engine!E4<>"","",SDK_RenderDigit("Auto",$Q$9,_Engine!E16,2))} | P7: {=IF(_Engine!E4<>"","",SDK_RenderDigit("Auto",$Q$9,_Engine!E16,3))} | R7: {=_xlfn.LET(_xlpm.r,QUOTIENT(ROW()-4,3)+1,_xlpm.c,QUOTIENT(COLUMN()-2,4)+1,_xlpm.live,INDEX(_Engine!$B$3:$J$11,_xlpm.r,_xlpm.c),_xlpm.cand,INDEX(_Engine!$B$15:$J$23,_xlpm.r,_xlpm.c),_xlpm.bad,INDEX(_Engine!$B$51:$J$59,_xlpm.r,_xlpm.c),_xlpm.note,INDEX($B$4:$AK$30,3*_xlpm.r,4*_xlpm.c),_xlpm.coord,"R"&_xlpm.r&"C"&_xlpm.c,_xlpm.role,SDK_CoordRole(_Engine!$B$88,_xlpm.coord),_xlpm.mark,IF(_xlpm.bad,"✖",IF($AS$11="Off","",IF(_xlpm.role="TARGET","▼",IF(_xlpm.role="SOURCE","●","")))),_xlpm.digit,IF(_xlpm.live<>"","",SDK_RenderDigit("Auto",_xlpm.note,_xlpm.cand,1)),_xlfn.TEXTJOIN(" ",TRUE,_xlpm.mark,_xlpm.digit))} | S7: {=IF(_Engine!F4<>"","",SDK_RenderDigit("Auto",$U$9,_Engine!F16,2))} | T7: {=IF(_Engine!F4<>"","",SDK_RenderDigit("Auto",$U$9,_Engine!F16,3))} | V7: {=_xlfn.LET(_xlpm.r,QUOTIENT(ROW()-4,3)+1,_xlpm.c,QUOTIENT(COLUMN()-2,4)+1,_xlpm.live,INDEX(_Engine!$B$3:$J$11,_xlpm.r,_xlpm.c),_xlpm.cand,INDEX(_Engine!$B$15:$J$23,_xlpm.r,_xlpm.c),_xlpm.bad,INDEX(_Engine!$B$51:$J$59,_xlpm.r,_xlpm.c),_xlpm.note,INDEX($B$4:$AK$30,3*_xlpm.r,4*_xlpm.c),_xlpm.coord,"R"&_xlpm.r&"C"&_xlpm.c,_xlpm.role,SDK_CoordRole(_Engine!$B$88,_xlpm.coord),_xlpm.mark,IF(_xlpm.bad,"✖",IF($AS$11="Off","",IF(_xlpm.role="TARGET","▼",IF(_xlpm.role="SOURCE","●","")))),_xlpm.digit,IF(_xlpm.live<>"","",SDK_RenderDigit("Auto",_xlpm.note,_xlpm.cand,1)),_xlfn.TEXTJOIN(" ",TRUE,_xlpm.mark,_xlpm.digit))} | W7: {=IF(_Engine!G4<>"","",SDK_RenderDigit("Auto",$Y$9,_Engine!G16,2))} | X7: {=IF(_Engine!G4<>"","",SDK_RenderDigit("Auto",$Y$9,_Engine!G16,3))} | Z7: {=_xlfn.LET(_xlpm.r,QUOTIENT(ROW()-4,3)+1,_xlpm.c,QUOTIENT(COLUMN()-2,4)+1,_xlpm.live,INDEX(_Engine!$B$3:$J$11,_xlpm.r,_xlpm.c),_xlpm.cand,INDEX(_Engine!$B$15:$J$23,_xlpm.r,_xlpm.c),_xlpm.bad,INDEX(_Engine!$B$51:$J$59,_xlpm.r,_xlpm.c),_xlpm.note,INDEX($B$4:$AK$30,3*_xlpm.r,4*_xlpm.c),_xlpm.coord,"R"&_xlpm.r&"C"&_xlpm.c,_xlpm.role,SDK_CoordRole(_Engine!$B$88,_xlpm.coord),_xlpm.mark,IF(_xlpm.bad,"✖",IF($AS$11="Off","",IF(_xlpm.role="TARGET","▼",IF(_xlpm.role="SOURCE","●","")))),_xlpm.digit,IF(_xlpm.live<>"","",SDK_RenderDigit("Auto",_xlpm.note,_xlpm.cand,1)),_xlfn.TEXTJOIN(" ",TRUE,_xlpm.mark,_xlpm.digit))} | AA7: {=IF(_Engine!H4<>"","",SDK_RenderDigit("Auto",$AC$9,_Engine!H16,2))} | AB7: {=IF(_Engine!H4<>"","",SDK_RenderDigit("Auto",$AC$9,_Engine!H16,3))} -> 3 | AD7: {=_xlfn.LET(_xlpm.r,QUOTIENT(ROW()-4,3)+1,_xlpm.c,QUOTIENT(COLUMN()-2,4)+1,_xlpm.live,INDEX(_Engine!$B$3:$J$11,_xlpm.r,_xlpm.c),_xlpm.cand,INDEX(_Engine!$B$15:$J$23,_xlpm.r,_xlpm.c),_xlpm.bad,INDEX(_Engine!$B$51:$J$59,_xlpm.r,_xlpm.c),_xlpm.note,INDEX($B$4:$AK$30,3*_xlpm.r,4*_xlpm.c),_xlpm.coord,"R"&_xlpm.r&"C"&_xlpm.c,_xlpm.role,SDK_CoordRole(_Engine!$B$88,_xlpm.coord),_xlpm.mark,IF(_xlpm.bad,"✖",IF($AS$11="Off","",IF(_xlpm.role="TARGET","▼",IF(_xlpm.role="SOURCE","●","")))),_xlpm.digit,IF(_xlpm.live<>"","",SDK_RenderDigit("Auto",_xlpm.note,_xlpm.cand,1)),_xlfn.TEXTJOIN(" ",TRUE,_xlpm.mark,_xlpm.digit))} | AE7: {=IF(_Engine!I4<>"","",SDK_RenderDigit("Auto",$AG$9,_Engine!I16,2))} -> 2 | AF7: {=IF(_Engine!I4<>"","",SDK_RenderDigit("Auto",$AG$9,_Engine!I16,3))} -> 3 | AH7: {=_xlfn.LET(_xlpm.r,QUOTIENT(ROW()-4,3)+1,_xlpm.c,QUOTIENT(COLUMN()-2,4)+1,_xlpm.live,INDEX(_Engine!$B$3:$J$11,_xlpm.r,_xlpm.c),_xlpm.cand,INDEX(_Engine!$B$15:$J$23,_xlpm.r,_xlpm.c),_xlpm.bad,INDEX(_Engine!$B$51:$J$59,_xlpm.r,_xlpm.c),_xlpm.note,INDEX($B$4:$AK$30,3*_xlpm.r,4*_xlpm.c),_xlpm.coord,"R"&_xlpm.r&"C"&_xlpm.c,_xlpm.role,SDK_CoordRole(_Engine!$B$88,_xlpm.coord),_xlpm.mark,IF(_xlpm.bad,"✖",IF($AS$11="Off","",IF(_xlpm.role="TARGET","▼",IF(_xlpm.role="SOURCE","●","")))),_xlpm.digit,IF(_xlpm.live<>"","",SDK_RenderDigit("Auto",_xlpm.note,_xlpm.cand,1)),_xlfn.TEXTJOIN(" ",TRUE,_xlpm.mark,_xlpm.digit))} | AI7: {=IF(_Engine!J4<>"","",SDK_RenderDigit("Auto",$AK$9,_Engine!J16,2))} -> 2 | AJ7: {=IF(_Engine!J4<>"","",SDK_RenderDigit("Auto",$AK$9,_Engine!J16,3))} | AM7: REMAINING | AU7: CONFLICTS | BC7: CANDIDATES
B8: {=_xlfn.LET(_xlpm.r,QUOTIENT(ROW()-5,3)+1,_xlpm.c,QUOTIENT(COLUMN()-2,4)+1,_xlpm.live,INDEX(_Engine!$B$3:$J$11,_xlpm.r,_xlpm.c),_xlpm.cand,INDEX(_Engine!$B$15:$J$23,_xlpm.r,_xlpm.c),_xlpm.note,INDEX($B$4:$AK$30,3*_xlpm.r,4*_xlpm.c),IF(_xlpm.live<>"","",_xlfn.TEXTJOIN("·",TRUE,SDK_RenderDigit("Auto",_xlpm.note,_xlpm.cand,4),SDK_RenderDigit("Auto",_xlpm.note,_xlpm.cand,5))))} | C8: =_Engine!B28 -> 6 | D8: {=IF(_Engine!B4<>"","",SDK_RenderDigit("Auto",$E$9,_Engine!B16,6))} | F8: {=_xlfn.LET(_xlpm.r,QUOTIENT(ROW()-5,3)+1,_xlpm.c,QUOTIENT(COLUMN()-2,4)+1,_xlpm.live,INDEX(_Engine!$B$3:$J$11,_xlpm.r,_xlpm.c),_xlpm.cand,INDEX(_Engine!$B$15:$J$23,_xlpm.r,_xlpm.c),_xlpm.note,INDEX($B$4:$AK$30,3*_xlpm.r,4*_xlpm.c),IF(_xlpm.live<>"","",_xlfn.TEXTJOIN("·",TRUE,SDK_RenderDigit("Auto",_xlpm.note,_xlpm.cand,4),SDK_RenderDigit("Auto",_xlpm.note,_xlpm.cand,5))))} -> 4 | H8: {=IF(_Engine!C4<>"","",SDK_RenderDigit("Auto",$I$9,_Engine!C16,6))} | J8: {=_xlfn.LET(_xlpm.r,QUOTIENT(ROW()-5,3)+1,_xlpm.c,QUOTIENT(COLUMN()-2,4)+1,_xlpm.live,INDEX(_Engine!$B$3:$J$11,_xlpm.r,_xlpm.c),_xlpm.cand,INDEX(_Engine!$B$15:$J$23,_xlpm.r,_xlpm.c),_xlpm.note,INDEX($B$4:$AK$30,3*_xlpm.r,4*_xlpm.c),IF(_xlpm.live<>"","",_xlfn.TEXTJOIN("·",TRUE,SDK_RenderDigit("Auto",_xlpm.note,_xlpm.cand,4),SDK_RenderDigit("Auto",_xlpm.note,_xlpm.cand,5))))} -> 4 | L8: {=IF(_Engine!D4<>"","",SDK_RenderDigit("Auto",$M$9,_Engine!D16,6))} | N8: {=_xlfn.LET(_xlpm.r,QUOTIENT(ROW()-5,3)+1,_xlpm.c,QUOTIENT(COLUMN()-2,4)+1,_xlpm.live,INDEX(_Engine!$B$3:$J$11,_xlpm.r,_xlpm.c),_xlpm.cand,INDEX(_Engine!$B$15:$J$23,_xlpm.r,_xlpm.c),_xlpm.note,INDEX($B$4:$AK$30,3*_xlpm.r,4*_xlpm.c),IF(_xlpm.live<>"","",_xlfn.TEXTJOIN("·",TRUE,SDK_RenderDigit("Auto",_xlpm.note,_xlpm.cand,4),SDK_RenderDigit("Auto",_xlpm.note,_xlpm.cand,5))))} | O8: =_Engine!E28 -> 1 | P8: {=IF(_Engine!E4<>"","",SDK_RenderDigit("Auto",$Q$9,_Engine!E16,6))} | R8: {=_xlfn.LET(_xlpm.r,QUOTIENT(ROW()-5,3)+1,_xlpm.c,QUOTIENT(COLUMN()-2,4)+1,_xlpm.live,INDEX(_Engine!$B$3:$J$11,_xlpm.r,_xlpm.c),_xlpm.cand,INDEX(_Engine!$B$15:$J$23,_xlpm.r,_xlpm.c),_xlpm.note,INDEX($B$4:$AK$30,3*_xlpm.r,4*_xlpm.c),IF(_xlpm.live<>"","",_xlfn.TEXTJOIN("·",TRUE,SDK_RenderDigit("Auto",_xlpm.note,_xlpm.cand,4),SDK_RenderDigit("Auto",_xlpm.note,_xlpm.cand,5))))} | S8: =_Engine!F28 -> 9 | T8: {=IF(_Engine!F4<>"","",SDK_RenderDigit("Auto",$U$9,_Engine!F16,6))} | V8: {=_xlfn.LET(_xlpm.r,QUOTIENT(ROW()-5,3)+1,_xlpm.c,QUOTIENT(COLUMN()-2,4)+1,_xlpm.live,INDEX(_Engine!$B$3:$J$11,_xlpm.r,_xlpm.c),_xlpm.cand,INDEX(_Engine!$B$15:$J$23,_xlpm.r,_xlpm.c),_xlpm.note,INDEX($B$4:$AK$30,3*_xlpm.r,4*_xlpm.c),IF(_xlpm.live<>"","",_xlfn.TEXTJOIN("·",TRUE,SDK_RenderDigit("Auto",_xlpm.note,_xlpm.cand,4),SDK_RenderDigit("Auto",_xlpm.note,_xlpm.cand,5))))} | W8: =_Engine!G28 -> 5 | X8: {=IF(_Engine!G4<>"","",SDK_RenderDigit("Auto",$Y$9,_Engine!G16,6))} | Z8: {=_xlfn.LET(_xlpm.r,QUOTIENT(ROW()-5,3)+1,_xlpm.c,QUOTIENT(COLUMN()-2,4)+1,_xlpm.live,INDEX(_Engine!$B$3:$J$11,_xlpm.r,_xlpm.c),_xlpm.cand,INDEX(_Engine!$B$15:$J$23,_xlpm.r,_xlpm.c),_xlpm.note,INDEX($B$4:$AK$30,3*_xlpm.r,4*_xlpm.c),IF(_xlpm.live<>"","",_xlfn.TEXTJOIN("·",TRUE,SDK_RenderDigit("Auto",_xlpm.note,_xlpm.cand,4),SDK_RenderDigit("Auto",_xlpm.note,_xlpm.cand,5))))} -> 4 | AB8: {=IF(_Engine!H4<>"","",SDK_RenderDigit("Auto",$AC$9,_Engine!H16,6))} | AD8: {=_xlfn.LET(_xlpm.r,QUOTIENT(ROW()-5,3)+1,_xlpm.c,QUOTIENT(COLUMN()-2,4)+1,_xlpm.live,INDEX(_Engine!$B$3:$J$11,_xlpm.r,_xlpm.c),_xlpm.cand,INDEX(_Engine!$B$15:$J$23,_xlpm.r,_xlpm.c),_xlpm.note,INDEX($B$4:$AK$30,3*_xlpm.r,4*_xlpm.c),IF(_xlpm.live<>"","",_xlfn.TEXTJOIN("·",TRUE,SDK_RenderDigit("Auto",_xlpm.note,_xlpm.cand,4),SDK_RenderDigit("Auto",_xlpm.note,_xlpm.cand,5))))} -> 4 | AF8: {=IF(_Engine!I4<>"","",SDK_RenderDigit("Auto",$AG$9,_Engine!I16,6))} | AH8: {=_xlfn.LET(_xlpm.r,QUOTIENT(ROW()-5,3)+1,_xlpm.c,QUOTIENT(COLUMN()-2,4)+1,_xlpm.live,INDEX(_Engine!$B$3:$J$11,_xlpm.r,_xlpm.c),_xlpm.cand,INDEX(_Engine!$B$15:$J$23,_xlpm.r,_xlpm.c),_xlpm.note,INDEX($B$4:$AK$30,3*_xlpm.r,4*_xlpm.c),IF(_xlpm.live<>"","",_xlfn.TEXTJOIN("·",TRUE,SDK_RenderDigit("Auto",_xlpm.note,_xlpm.cand,4),SDK_RenderDigit("Auto",_xlpm.note,_xlpm.cand,5))))} -> 4 | AJ8: {=IF(_Engine!J4<>"","",SDK_RenderDigit("Auto",$AK$9,_Engine!J16,6))} | AM8: =81-COUNT(_Engine!$B$3:$J$11) -> 51 | AU8: =COUNTIF(_Engine!$B$51:$J$59,TRUE) -> 0 | BC8: AUTO
B9: {=IF(_Engine!B4<>"","",SDK_RenderDigit("Auto",$E$9,_Engine!B16,7))} | C9: {=IF(_Engine!B4<>"","",SDK_RenderDigit("Auto",$E$9,_Engine!B16,8))} | D9: {=IF(_Engine!B4<>"","",SDK_RenderDigit("Auto",$E$9,_Engine!B16,9))} | E9: ="" | F9: {=IF(_Engine!C4<>"","",SDK_RenderDigit("Auto",$I$9,_Engine!C16,7))} -> 7 | G9: {=IF(_Engine!C4<>"","",SDK_RenderDigit("Auto",$I$9,_Engine!C16,8))} | H9: {=IF(_Engine!C4<>"","",SDK_RenderDigit("Auto",$I$9,_Engine!C16,9))} | I9: ="" | J9: {=IF(_Engine!D4<>"","",SDK_RenderDigit("Auto",$M$9,_Engine!D16,7))} -> 7 | K9: {=IF(_Engine!D4<>"","",SDK_RenderDigit("Auto",$M$9,_Engine!D16,8))} | L9: {=IF(_Engine!D4<>"","",SDK_RenderDigit("Auto",$M$9,_Engine!D16,9))} | M9: ="" | N9: {=IF(_Engine!E4<>"","",SDK_RenderDigit("Auto",$Q$9,_Engine!E16,7))} | O9: {=IF(_Engine!E4<>"","",SDK_RenderDigit("Auto",$Q$9,_Engine!E16,8))} | P9: {=IF(_Engine!E4<>"","",SDK_RenderDigit("Auto",$Q$9,_Engine!E16,9))} | Q9: ="" | R9: {=IF(_Engine!F4<>"","",SDK_RenderDigit("Auto",$U$9,_Engine!F16,7))} | S9: {=IF(_Engine!F4<>"","",SDK_RenderDigit("Auto",$U$9,_Engine!F16,8))} | T9: {=IF(_Engine!F4<>"","",SDK_RenderDigit("Auto",$U$9,_Engine!F16,9))} | U9: ="" | V9: {=IF(_Engine!G4<>"","",SDK_RenderDigit("Auto",$Y$9,_Engine!G16,7))} | W9: {=IF(_Engine!G4<>"","",SDK_RenderDigit("Auto",$Y$9,_Engine!G16,8))} | X9: {=IF(_Engine!G4<>"","",SDK_RenderDigit("Auto",$Y$9,_Engine!G16,9))} | Y9: ="" | Z9: {=IF(_Engine!H4<>"","",SDK_RenderDigit("Auto",$AC$9,_Engine!H16,7))} -> 7 | AA9: {=IF(_Engine!H4<>"","",SDK_RenderDigit("Auto",$AC$9,_Engine!H16,8))} -> 8 | AB9: {=IF(_Engine!H4<>"","",SDK_RenderDigit("Auto",$AC$9,_Engine!H16,9))} | AC9: ="" | AD9: {=IF(_Engine!I4<>"","",SDK_RenderDigit("Auto",$AG$9,_Engine!I16,7))} | AE9: {=IF(_Engine!I4<>"","",SDK_RenderDigit("Auto",$AG$9,_Engine!I16,8))} | AF9: {=IF(_Engine!I4<>"","",SDK_RenderDigit("Auto",$AG$9,_Engine!I16,9))} | AG9: ="" | AH9: {=IF(_Engine!J4<>"","",SDK_RenderDigit("Auto",$AK$9,_Engine!J16,7))} -> 7 | AI9: {=IF(_Engine!J4<>"","",SDK_RenderDigit("Auto",$AK$9,_Engine!J16,8))} -> 8 | AJ9: {=IF(_Engine!J4<>"","",SDK_RenderDigit("Auto",$AK$9,_Engine!J16,9))} | AK9: =""
B10: {=_xlfn.LET(_xlpm.r,QUOTIENT(ROW()-4,3)+1,_xlpm.c,QUOTIENT(COLUMN()-2,4)+1,_xlpm.live,INDEX(_Engine!$B$3:$J$11,_xlpm.r,_xlpm.c),_xlpm.cand,INDEX(_Engine!$B$15:$J$23,_xlpm.r,_xlpm.c),_xlpm.bad,INDEX(_Engine!$B$51:$J$59,_xlpm.r,_xlpm.c),_xlpm.note,INDEX($B$4:$AK$30,3*_xlpm.r,4*_xlpm.c),_xlpm.coord,"R"&_xlpm.r&"C"&_xlpm.c,_xlpm.role,SDK_CoordRole(_Engine!$B$88,_xlpm.coord),_xlpm.mark,IF(_xlpm.bad,"✖",IF($AS$11="Off","",IF(_xlpm.role="TARGET","▼",IF(_xlpm.role="SOURCE","●","")))),_xlpm.digit,IF(_xlpm.live<>"","",SDK_RenderDigit("Auto",_xlpm.note,_xlpm.cand,1)),_xlfn.TEXTJOIN(" ",TRUE,_xlpm.mark,_xlpm.digit))} -> 1 | C10: {=IF(_Engine!B5<>"","",SDK_RenderDigit("Auto",$E$12,_Engine!B17,2))} -> 2 | D10: {=IF(_Engine!B5<>"","",SDK_RenderDigit("Auto",$E$12,_Engine!B17,3))} | F10: {=_xlfn.LET(_xlpm.r,QUOTIENT(ROW()-4,3)+1,_xlpm.c,QUOTIENT(COLUMN()-2,4)+1,_xlpm.live,INDEX(_Engine!$B$3:$J$11,_xlpm.r,_xlpm.c),_xlpm.cand,INDEX(_Engine!$B$15:$J$23,_xlpm.r,_xlpm.c),_xlpm.bad,INDEX(_Engine!$B$51:$J$59,_xlpm.r,_xlpm.c),_xlpm.note,INDEX($B$4:$AK$30,3*_xlpm.r,4*_xlpm.c),_xlpm.coord,"R"&_xlpm.r&"C"&_xlpm.c,_xlpm.role,SDK_CoordRole(_Engine!$B$88,_xlpm.coord),_xlpm.mark,IF(_xlpm.bad,"✖",IF($AS$11="Off","",IF(_xlpm.role="TARGET","▼",IF(_xlpm.role="SOURCE","●","")))),_xlpm.digit,IF(_xlpm.live<>"","",SDK_RenderDigit("Auto",_xlpm.note,_xlpm.cand,1)),_xlfn.TEXTJOIN(" ",TRUE,_xlpm.mark,_xlpm.digit))} | G10: {=IF(_Engine!C5<>"","",SDK_RenderDigit("Auto",$I$12,_Engine!C17,2))} | H10: {=IF(_Engine!C5<>"","",SDK_RenderDigit("Auto",$I$12,_Engine!C17,3))} | J10: {=_xlfn.LET(_xlpm.r,QUOTIENT(ROW()-4,3)+1,_xlpm.c,QUOTIENT(COLUMN()-2,4)+1,_xlpm.live,INDEX(_Engine!$B$3:$J$11,_xlpm.r,_xlpm.c),_xlpm.cand,INDEX(_Engine!$B$15:$J$23,_xlpm.r,_xlpm.c),_xlpm.bad,INDEX(_Engine!$B$51:$J$59,_xlpm.r,_xlpm.c),_xlpm.note,INDEX($B$4:$AK$30,3*_xlpm.r,4*_xlpm.c),_xlpm.coord,"R"&_xlpm.r&"C"&_xlpm.c,_xlpm.role,SDK_CoordRole(_Engine!$B$88,_xlpm.coord),_xlpm.mark,IF(_xlpm.bad,"✖",IF($AS$11="Off","",IF(_xlpm.role="TARGET","▼",IF(_xlpm.role="SOURCE","●","")))),_xlpm.digit,IF(_xlpm.live<>"","",SDK_RenderDigit("Auto",_xlpm.note,_xlpm.cand,1)),_xlfn.TEXTJOIN(" ",TRUE,_xlpm.mark,_xlpm.digit))} | K10: {=IF(_Engine!D5<>"","",SDK_RenderDigit("Auto",$M$12,_Engine!D17,2))} | L10: {=IF(_Engine!D5<>"","",SDK_RenderDigit("Auto",$M$12,_Engine!D17,3))} | N10: {=_xlfn.LET(_xlpm.r,QUOTIENT(ROW()-4,3)+1,_xlpm.c,QUOTIENT(COLUMN()-2,4)+1,_xlpm.live,INDEX(_Engine!$B$3:$J$11,_xlpm.r,_xlpm.c),_xlpm.cand,INDEX(_Engine!$B$15:$J$23,_xlpm.r,_xlpm.c),_xlpm.bad,INDEX(_Engine!$B$51:$J$59,_xlpm.r,_xlpm.c),_xlpm.note,INDEX($B$4:$AK$30,3*_xlpm.r,4*_xlpm.c),_xlpm.coord,"R"&_xlpm.r&"C"&_xlpm.c,_xlpm.role,SDK_CoordRole(_Engine!$B$88,_xlpm.coord),_xlpm.mark,IF(_xlpm.bad,"✖",IF($AS$11="Off","",IF(_xlpm.role="TARGET","▼",IF(_xlpm.role="SOURCE","●","")))),_xlpm.digit,IF(_xlpm.live<>"","",SDK_RenderDigit("Auto",_xlpm.note,_xlpm.cand,1)),_xlfn.TEXTJOIN(" ",TRUE,_xlpm.mark,_xlpm.digit))} | O10: {=IF(_Engine!E5<>"","",SDK_RenderDigit("Auto",$Q$12,_Engine!E17,2))} -> 2 | P10: {=IF(_Engine!E5<>"","",SDK_RenderDigit("Auto",$Q$12,_Engine!E17,3))} -> 3 | R10: {=_xlfn.LET(_xlpm.r,QUOTIENT(ROW()-4,3)+1,_xlpm.c,QUOTIENT(COLUMN()-2,4)+1,_xlpm.live,INDEX(_Engine!$B$3:$J$11,_xlpm.r,_xlpm.c),_xlpm.cand,INDEX(_Engine!$B$15:$J$23,_xlpm.r,_xlpm.c),_xlpm.bad,INDEX(_Engine!$B$51:$J$59,_xlpm.r,_xlpm.c),_xlpm.note,INDEX($B$4:$AK$30,3*_xlpm.r,4*_xlpm.c),_xlpm.coord,"R"&_xlpm.r&"C"&_xlpm.c,_xlpm.role,SDK_CoordRole(_Engine!$B$88,_xlpm.coord),_xlpm.mark,IF(_xlpm.bad,"✖",IF($AS$11="Off","",IF(_xlpm.role="TARGET","▼",IF(_xlpm.role="SOURCE","●","")))),_xlpm.digit,IF(_xlpm.live<>"","",SDK_RenderDigit("Auto",_xlpm.note,_xlpm.cand,1)),_xlfn.TEXTJOIN(" ",TRUE,_xlpm.mark,_xlpm.digit))} | S10: {=IF(_Engine!F5<>"","",SDK_RenderDigit("Auto",$U$12,_Engine!F17,2))} | T10: {=IF(_Engine!F5<>"","",SDK_RenderDigit("Auto",$U$12,_Engine!F17,3))} -> 3 | V10: {=_xlfn.LET(_xlpm.r,QUOTIENT(ROW()-4,3)+1,_xlpm.c,QUOTIENT(COLUMN()-2,4)+1,_xlpm.live,INDEX(_Engine!$B$3:$J$11,_xlpm.r,_xlpm.c),_xlpm.cand,INDEX(_Engine!$B$15:$J$23,_xlpm.r,_xlpm.c),_xlpm.bad,INDEX(_Engine!$B$51:$J$59,_xlpm.r,_xlpm.c),_xlpm.note,INDEX($B$4:$AK$30,3*_xlpm.r,4*_xlpm.c),_xlpm.coord,"R"&_xlpm.r&"C"&_xlpm.c,_xlpm.role,SDK_CoordRole(_Engine!$B$88,_xlpm.coord),_xlpm.mark,IF(_xlpm.bad,"✖",IF($AS$11="Off","",IF(_xlpm.role="TARGET","▼",IF(_xlpm.role="SOURCE","●","")))),_xlpm.digit,IF(_xlpm.live<>"","",SDK_RenderDigit("Auto",_xlpm.note,_xlpm.cand,1)),_xlfn.TEXTJOIN(" ",TRUE,_xlpm.mark,_xlpm.digit))} | W10: {=IF(_Engine!G5<>"","",SDK_RenderDigit("Auto",$Y$12,_Engine!G17,2))} -> 2 | X10: {=IF(_Engine!G5<>"","",SDK_RenderDigit("Auto",$Y$12,_Engine!G17,3))} | Z10: {=_xlfn.LET(_xlpm.r,QUOTIENT(ROW()-4,3)+1,_xlpm.c,QUOTIENT(COLUMN()-2,4)+1,_xlpm.live,INDEX(_Engine!$B$3:$J$11,_xlpm.r,_xlpm.c),_xlpm.cand,INDEX(_Engine!$B$15:$J$23,_xlpm.r,_xlpm.c),_xlpm.bad,INDEX(_Engine!$B$51:$J$59,_xlpm.r,_xlpm.c),_xlpm.note,INDEX($B$4:$AK$30,3*_xlpm.r,4*_xlpm.c),_xlpm.coord,"R"&_xlpm.r&"C"&_xlpm.c,_xlpm.role,SDK_CoordRole(_Engine!$B$88,_xlpm.coord),_xlpm.mark,IF(_xlpm.bad,"✖",IF($AS$11="Off","",IF(_xlpm.role="TARGET","▼",IF(_xlpm.role="SOURCE","●","")))),_xlpm.digit,IF(_xlpm.live<>"","",SDK_RenderDigit("Auto",_xlpm.note,_xlpm.cand,1)),_xlfn.TEXTJOIN(" ",TRUE,_xlpm.mark,_xlpm.digit))} -> 1 | AA10: {=IF(_Engine!H5<>"","",SDK_RenderDigit("Auto",$AC$12,_Engine!H17,2))} | AB10: {=IF(_Engine!H5<>"","",SDK_RenderDigit("Auto",$AC$12,_Engine!H17,3))} -> 3 | AD10: {=_xlfn.LET(_xlpm.r,QUOTIENT(ROW()-4,3)+1,_xlpm.c,QUOTIENT(COLUMN()-2,4)+1,_xlpm.live,INDEX(_Engine!$B$3:$J$11,_xlpm.r,_xlpm.c),_xlpm.cand,INDEX(_Engine!$B$15:$J$23,_xlpm.r,_xlpm.c),_xlpm.bad,INDEX(_Engine!$B$51:$J$59,_xlpm.r,_xlpm.c),_xlpm.note,INDEX($B$4:$AK$30,3*_xlpm.r,4*_xlpm.c),_xlpm.coord,"R"&_xlpm.r&"C"&_xlpm.c,_xlpm.role,SDK_CoordRole(_Engine!$B$88,_xlpm.coord),_xlpm.mark,IF(_xlpm.bad,"✖",IF($AS$11="Off","",IF(_xlpm.role="TARGET","▼",IF(_xlpm.role="SOURCE","●","")))),_xlpm.digit,IF(_xlpm.live<>"","",SDK_RenderDigit("Auto",_xlpm.note,_xlpm.cand,1)),_xlfn.TEXTJOIN(" ",TRUE,_xlpm.mark,_xlpm.digit))} | AE10: {=IF(_Engine!I5<>"","",SDK_RenderDigit("Auto",$AG$12,_Engine!I17,2))} | AF10: {=IF(_Engine!I5<>"","",SDK_RenderDigit("Auto",$AG$12,_Engine!I17,3))} | AH10: {=_xlfn.LET(_xlpm.r,QUOTIENT(ROW()-4,3)+1,_xlpm.c,QUOTIENT(COLUMN()-2,4)+1,_xlpm.live,INDEX(_Engine!$B$3:$J$11,_xlpm.r,_xlpm.c),_xlpm.cand,INDEX(_Engine!$B$15:$J$23,_xlpm.r,_xlpm.c),_xlpm.bad,INDEX(_Engine!$B$51:$J$59,_xlpm.r,_xlpm.c),_xlpm.note,INDEX($B$4:$AK$30,3*_xlpm.r,4*_xlpm.c),_xlpm.coord,"R"&_xlpm.r&"C"&_xlpm.c,_xlpm.role,SDK_CoordRole(_Engine!$B$88,_xlpm.coord),_xlpm.mark,IF(_xlpm.bad,"✖",IF($AS$11="Off","",IF(_xlpm.role="TARGET","▼",IF(_xlpm.role="SOURCE","●","")))),_xlpm.digit,IF(_xlpm.live<>"","",SDK_RenderDigit("Auto",_xlpm.note,_xlpm.cand,1)),_xlfn.TEXTJOIN(" ",TRUE,_xlpm.mark,_xlpm.digit))} | AI10: {=IF(_Engine!J5<>"","",SDK_RenderDigit("Auto",$AK$12,_Engine!J17,2))} -> 2 | AJ10: {=IF(_Engine!J5<>"","",SDK_RenderDigit("Auto",$AK$12,_Engine!J17,3))} | AM10: COACH
B11: {=_xlfn.LET(_xlpm.r,QUOTIENT(ROW()-5,3)+1,_xlpm.c,QUOTIENT(COLUMN()-2,4)+1,_xlpm.live,INDEX(_Engine!$B$3:$J$11,_xlpm.r,_xlpm.c),_xlpm.cand,INDEX(_Engine!$B$15:$J$23,_xlpm.r,_xlpm.c),_xlpm.note,INDEX($B$4:$AK$30,3*_xlpm.r,4*_xlpm.c),IF(_xlpm.live<>"","",_xlfn.TEXTJOIN("·",TRUE,SDK_RenderDigit("Auto",_xlpm.note,_xlpm.cand,4),SDK_RenderDigit("Auto",_xlpm.note,_xlpm.cand,5))))} | D11: {=IF(_Engine!B5<>"","",SDK_RenderDigit("Auto",$E$12,_Engine!B17,6))} | F11: {=_xlfn.LET(_xlpm.r,QUOTIENT(ROW()-5,3)+1,_xlpm.c,QUOTIENT(COLUMN()-2,4)+1,_xlpm.live,INDEX(_Engine!$B$3:$J$11,_xlpm.r,_xlpm.c),_xlpm.cand,INDEX(_Engine!$B$15:$J$23,_xlpm.r,_xlpm.c),_xlpm.note,INDEX($B$4:$AK$30,3*_xlpm.r,4*_xlpm.c),IF(_xlpm.live<>"","",_xlfn.TEXTJOIN("·",TRUE,SDK_RenderDigit("Auto",_xlpm.note,_xlpm.cand,4),SDK_RenderDigit("Auto",_xlpm.note,_xlpm.cand,5))))} | G11: =_Engine!C29 -> 9 | H11: {=IF(_Engine!C5<>"","",SDK_RenderDigit("Auto",$I$12,_Engine!C17,6))} | J11: {=_xlfn.LET(_xlpm.r,QUOTIENT(ROW()-5,3)+1,_xlpm.c,QUOTIENT(COLUMN()-2,4)+1,_xlpm.live,INDEX(_Engine!$B$3:$J$11,_xlpm.r,_xlpm.c),_xlpm.cand,INDEX(_Engine!$B$15:$J$23,_xlpm.r,_xlpm.c),_xlpm.note,INDEX($B$4:$AK$30,3*_xlpm.r,4*_xlpm.c),IF(_xlpm.live<>"","",_xlfn.TEXTJOIN("·",TRUE,SDK_RenderDigit("Auto",_xlpm.note,_xlpm.cand,4),SDK_RenderDigit("Auto",_xlpm.note,_xlpm.cand,5))))} | K11: =_Engine!D29 -> 8 | L11: {=IF(_Engine!D5<>"","",SDK_RenderDigit("Auto",$M$12,_Engine!D17,6))} | N11: {=_xlfn.LET(_xlpm.r,QUOTIENT(ROW()-5,3)+1,_xlpm.c,QUOTIENT(COLUMN()-2,4)+1,_xlpm.live,INDEX(_Engine!$B$3:$J$11,_xlpm.r,_xlpm.c),_xlpm.cand,INDEX(_Engine!$B$15:$J$23,_xlpm.r,_xlpm.c),_xlpm.note,INDEX($B$4:$AK$30,3*_xlpm.r,4*_xlpm.c),IF(_xlpm.live<>"","",_xlfn.TEXTJOIN("·",TRUE,SDK_RenderDigit("Auto",_xlpm.note,_xlpm.cand,4),SDK_RenderDigit("Auto",_xlpm.note,_xlpm.cand,5))))} | P11: {=IF(_Engine!E5<>"","",SDK_RenderDigit("Auto",$Q$12,_Engine!E17,6))} | R11: {=_xlfn.LET(_xlpm.r,QUOTIENT(ROW()-5,3)+1,_xlpm.c,QUOTIENT(COLUMN()-2,4)+1,_xlpm.live,INDEX(_Engine!$B$3:$J$11,_xlpm.r,_xlpm.c),_xlpm.cand,INDEX(_Engine!$B$15:$J$23,_xlpm.r,_xlpm.c),_xlpm.note,INDEX($B$4:$AK$30,3*_xlpm.r,4*_xlpm.c),IF(_xlpm.live<>"","",_xlfn.TEXTJOIN("·",TRUE,SDK_RenderDigit("Auto",_xlpm.note,_xlpm.cand,4),SDK_RenderDigit("Auto",_xlpm.note,_xlpm.cand,5))))} -> 4 | T11: {=IF(_Engine!F5<>"","",SDK_RenderDigit("Auto",$U$12,_Engine!F17,6))} | V11: {=_xlfn.LET(_xlpm.r,QUOTIENT(ROW()-5,3)+1,_xlpm.c,QUOTIENT(COLUMN()-2,4)+1,_xlpm.live,INDEX(_Engine!$B$3:$J$11,_xlpm.r,_xlpm.c),_xlpm.cand,INDEX(_Engine!$B$15:$J$23,_xlpm.r,_xlpm.c),_xlpm.note,INDEX($B$4:$AK$30,3*_xlpm.r,4*_xlpm.c),IF(_xlpm.live<>"","",_xlfn.TEXTJOIN("·",TRUE,SDK_RenderDigit("Auto",_xlpm.note,_xlpm.cand,4),SDK_RenderDigit("Auto",_xlpm.note,_xlpm.cand,5))))} -> 4 | X11: {=IF(_Engine!G5<>"","",SDK_RenderDigit("Auto",$Y$12,_Engine!G17,6))} | Z11: {=_xlfn.LET(_xlpm.r,QUOTIENT(ROW()-5,3)+1,_xlpm.c,QUOTIENT(COLUMN()-2,4)+1,_xlpm.live,INDEX(_Engine!$B$3:$J$11,_xlpm.r,_xlpm.c),_xlpm.cand,INDEX(_Engine!$B$15:$J$23,_xlpm.r,_xlpm.c),_xlpm.note,INDEX($B$4:$AK$30,3*_xlpm.r,4*_xlpm.c),IF(_xlpm.live<>"","",_xlfn.TEXTJOIN("·",TRUE,SDK_RenderDigit("Auto",_xlpm.note,_xlpm.cand,4),SDK_RenderDigit("Auto",_xlpm.note,_xlpm.cand,5))))} -> 4·5 | AB11: {=IF(_Engine!H5<>"","",SDK_RenderDigit("Auto",$AC$12,_Engine!H17,6))} | AD11: {=_xlfn.LET(_xlpm.r,QUOTIENT(ROW()-5,3)+1,_xlpm.c,QUOTIENT(COLUMN()-2,4)+1,_xlpm.live,INDEX(_Engine!$B$3:$J$11,_xlpm.r,_xlpm.c),_xlpm.cand,INDEX(_Engine!$B$15:$J$23,_xlpm.r,_xlpm.c),_xlpm.note,INDEX($B$4:$AK$30,3*_xlpm.r,4*_xlpm.c),IF(_xlpm.live<>"","",_xlfn.TEXTJOIN("·",TRUE,SDK_RenderDigit("Auto",_xlpm.note,_xlpm.cand,4),SDK_RenderDigit("Auto",_xlpm.note,_xlpm.cand,5))))} | AE11: =_Engine!I29 -> 6 | AF11: {=IF(_Engine!I5<>"","",SDK_RenderDigit("Auto",$AG$12,_Engine!I17,6))} | AH11: {=_xlfn.LET(_xlpm.r,QUOTIENT(ROW()-5,3)+1,_xlpm.c,QUOTIENT(COLUMN()-2,4)+1,_xlpm.live,INDEX(_Engine!$B$3:$J$11,_xlpm.r,_xlpm.c),_xlpm.cand,INDEX(_Engine!$B$15:$J$23,_xlpm.r,_xlpm.c),_xlpm.note,INDEX($B$4:$AK$30,3*_xlpm.r,4*_xlpm.c),IF(_xlpm.live<>"","",_xlfn.TEXTJOIN("·",TRUE,SDK_RenderDigit("Auto",_xlpm.note,_xlpm.cand,4),SDK_RenderDigit("Auto",_xlpm.note,_xlpm.cand,5))))} -> 4 | AJ11: {=IF(_Engine!J5<>"","",SDK_RenderDigit("Auto",$AK$12,_Engine!J17,6))} | AM11: MODE | AS11: Off
B12: {=IF(_Engine!B5<>"","",SDK_RenderDigit("Auto",$E$12,_Engine!B17,7))} | C12: {=IF(_Engine!B5<>"","",SDK_RenderDigit("Auto",$E$12,_Engine!B17,8))} | D12: {=IF(_Engine!B5<>"","",SDK_RenderDigit("Auto",$E$12,_Engine!B17,9))} | E12: ="" | F12: {=IF(_Engine!C5<>"","",SDK_RenderDigit("Auto",$I$12,_Engine!C17,7))} | G12: {=IF(_Engine!C5<>"","",SDK_RenderDigit("Auto",$I$12,_Engine!C17,8))} | H12: {=IF(_Engine!C5<>"","",SDK_RenderDigit("Auto",$I$12,_Engine!C17,9))} | I12: ="" | J12: {=IF(_Engine!D5<>"","",SDK_RenderDigit("Auto",$M$12,_Engine!D17,7))} | K12: {=IF(_Engine!D5<>"","",SDK_RenderDigit("Auto",$M$12,_Engine!D17,8))} | L12: {=IF(_Engine!D5<>"","",SDK_RenderDigit("Auto",$M$12,_Engine!D17,9))} | M12: ="" | N12: {=IF(_Engine!E5<>"","",SDK_RenderDigit("Auto",$Q$12,_Engine!E17,7))} | O12: {=IF(_Engine!E5<>"","",SDK_RenderDigit("Auto",$Q$12,_Engine!E17,8))} | P12: {=IF(_Engine!E5<>"","",SDK_RenderDigit("Auto",$Q$12,_Engine!E17,9))} | Q12: ="" | R12: {=IF(_Engine!F5<>"","",SDK_RenderDigit("Auto",$U$12,_Engine!F17,7))} | S12: {=IF(_Engine!F5<>"","",SDK_RenderDigit("Auto",$U$12,_Engine!F17,8))} | T12: {=IF(_Engine!F5<>"","",SDK_RenderDigit("Auto",$U$12,_Engine!F17,9))} | U12: ="" | V12: {=IF(_Engine!G5<>"","",SDK_RenderDigit("Auto",$Y$12,_Engine!G17,7))} | W12: {=IF(_Engine!G5<>"","",SDK_RenderDigit("Auto",$Y$12,_Engine!G17,8))} | X12: {=IF(_Engine!G5<>"","",SDK_RenderDigit("Auto",$Y$12,_Engine!G17,9))} | Y12: ="" | Z12: {=IF(_Engine!H5<>"","",SDK_RenderDigit("Auto",$AC$12,_Engine!H17,7))} -> 7 | AA12: {=IF(_Engine!H5<>"","",SDK_RenderDigit("Auto",$AC$12,_Engine!H17,8))} | AB12: {=IF(_Engine!H5<>"","",SDK_RenderDigit("Auto",$AC$12,_Engine!H17,9))} | AC12: ="" | AD12: {=IF(_Engine!I5<>"","",SDK_RenderDigit("Auto",$AG$12,_Engine!I17,7))} | AE12: {=IF(_Engine!I5<>"","",SDK_RenderDigit("Auto",$AG$12,_Engine!I17,8))} | AF12: {=IF(_Engine!I5<>"","",SDK_RenderDigit("Auto",$AG$12,_Engine!I17,9))} | AG12: ="" | AH12: {=IF(_Engine!J5<>"","",SDK_RenderDigit("Auto",$AK$12,_Engine!J17,7))} -> 7 | AI12: {=IF(_Engine!J5<>"","",SDK_RenderDigit("Auto",$AK$12,_Engine!J17,8))} | AJ12: {=IF(_Engine!J5<>"","",SDK_RenderDigit("Auto",$AK$12,_Engine!J17,9))} | AK12: ="" | AM12: {=IF($AS$11="Off","",IF(COUNTIF(_Engine!$B$51:$J$59,TRUE)>0,"Resolve the conflict before using Coach.",IF(_Engine!$B$99,_Engine!$B$98,IF($AS$11="Verify",IF(SDK_IsSolved(_Engine!$B$3:$J$11,_Engine!$B$39:$J$47),"Puzzle complete.",_xlfn.SWITCH(_Engine!$B$100,"VIABLE","VIABLE · At least one completion remains."&CHAR(10)&"Global search checked the full board. Return Mode to Off afterward.","NO SOLUTION","NO SOLUTION · Current entries cannot complete."&CHAR(10)&"Undo one or more recent entries. Return Mode to Off afterward.","CONFLICT","Resolve the conflict before using Coach.","SEARCH ERROR","SEARCH ERROR · Excel could not complete the global check."&CHAR(10)&"Return Coach to Off and try again.","")),IF($AS$11="Hint",_Engine!$B$88,_Engine!$B$89&CHAR(10)&_Engine!$B$90)))))}
B13: {=_xlfn.LET(_xlpm.r,QUOTIENT(ROW()-4,3)+1,_xlpm.c,QUOTIENT(COLUMN()-2,4)+1,_xlpm.live,INDEX(_Engine!$B$3:$J$11,_xlpm.r,_xlpm.c),_xlpm.cand,INDEX(_Engine!$B$15:$J$23,_xlpm.r,_xlpm.c),_xlpm.bad,INDEX(_Engine!$B$51:$J$59,_xlpm.r,_xlpm.c),_xlpm.note,INDEX($B$4:$AK$30,3*_xlpm.r,4*_xlpm.c),_xlpm.coord,"R"&_xlpm.r&"C"&_xlpm.c,_xlpm.role,SDK_CoordRole(_Engine!$B$88,_xlpm.coord),_xlpm.mark,IF(_xlpm.bad,"✖",IF($AS$11="Off","",IF(_xlpm.role="TARGET","▼",IF(_xlpm.role="SOURCE","●","")))),_xlpm.digit,IF(_xlpm.live<>"","",SDK_RenderDigit("Auto",_xlpm.note,_xlpm.cand,1)),_xlfn.TEXTJOIN(" ",TRUE,_xlpm.mark,_xlpm.digit))} | C13: {=IF(_Engine!B6<>"","",SDK_RenderDigit("Auto",$E$15,_Engine!B18,2))} | D13: {=IF(_Engine!B6<>"","",SDK_RenderDigit("Auto",$E$15,_Engine!B18,3))} | F13: {=_xlfn.LET(_xlpm.r,QUOTIENT(ROW()-4,3)+1,_xlpm.c,QUOTIENT(COLUMN()-2,4)+1,_xlpm.live,INDEX(_Engine!$B$3:$J$11,_xlpm.r,_xlpm.c),_xlpm.cand,INDEX(_Engine!$B$15:$J$23,_xlpm.r,_xlpm.c),_xlpm.bad,INDEX(_Engine!$B$51:$J$59,_xlpm.r,_xlpm.c),_xlpm.note,INDEX($B$4:$AK$30,3*_xlpm.r,4*_xlpm.c),_xlpm.coord,"R"&_xlpm.r&"C"&_xlpm.c,_xlpm.role,SDK_CoordRole(_Engine!$B$88,_xlpm.coord),_xlpm.mark,IF(_xlpm.bad,"✖",IF($AS$11="Off","",IF(_xlpm.role="TARGET","▼",IF(_xlpm.role="SOURCE","●","")))),_xlpm.digit,IF(_xlpm.live<>"","",SDK_RenderDigit("Auto",_xlpm.note,_xlpm.cand,1)),_xlfn.TEXTJOIN(" ",TRUE,_xlpm.mark,_xlpm.digit))} -> 1 | G13: {=IF(_Engine!C6<>"","",SDK_RenderDigit("Auto",$I$15,_Engine!C18,2))} -> 2 | H13: {=IF(_Engine!C6<>"","",SDK_RenderDigit("Auto",$I$15,_Engine!C18,3))} | J13: {=_xlfn.LET(_xlpm.r,QUOTIENT(ROW()-4,3)+1,_xlpm.c,QUOTIENT(COLUMN()-2,4)+1,_xlpm.live,INDEX(_Engine!$B$3:$J$11,_xlpm.r,_xlpm.c),_xlpm.cand,INDEX(_Engine!$B$15:$J$23,_xlpm.r,_xlpm.c),_xlpm.bad,INDEX(_Engine!$B$51:$J$59,_xlpm.r,_xlpm.c),_xlpm.note,INDEX($B$4:$AK$30,3*_xlpm.r,4*_xlpm.c),_xlpm.coord,"R"&_xlpm.r&"C"&_xlpm.c,_xlpm.role,SDK_CoordRole(_Engine!$B$88,_xlpm.coord),_xlpm.mark,IF(_xlpm.bad,"✖",IF($AS$11="Off","",IF(_xlpm.role="TARGET","▼",IF(_xlpm.role="SOURCE","●","")))),_xlpm.digit,IF(_xlpm.live<>"","",SDK_RenderDigit("Auto",_xlpm.note,_xlpm.cand,1)),_xlfn.TEXTJOIN(" ",TRUE,_xlpm.mark,_xlpm.digit))} -> 1 | K13: {=IF(_Engine!D6<>"","",SDK_RenderDigit("Auto",$M$15,_Engine!D18,2))} -> 2 | L13: {=IF(_Engine!D6<>"","",SDK_RenderDigit("Auto",$M$15,_Engine!D18,3))} | N13: {=_xlfn.LET(_xlpm.r,QUOTIENT(ROW()-4,3)+1,_xlpm.c,QUOTIENT(COLUMN()-2,4)+1,_xlpm.live,INDEX(_Engine!$B$3:$J$11,_xlpm.r,_xlpm.c),_xlpm.cand,INDEX(_Engine!$B$15:$J$23,_xlpm.r,_xlpm.c),_xlpm.bad,INDEX(_Engine!$B$51:$J$59,_xlpm.r,_xlpm.c),_xlpm.note,INDEX($B$4:$AK$30,3*_xlpm.r,4*_xlpm.c),_xlpm.coord,"R"&_xlpm.r&"C"&_xlpm.c,_xlpm.role,SDK_CoordRole(_Engine!$B$88,_xlpm.coord),_xlpm.mark,IF(_xlpm.bad,"✖",IF($AS$11="Off","",IF(_xlpm.role="TARGET","▼",IF(_xlpm.role="SOURCE","●","")))),_xlpm.digit,IF(_xlpm.live<>"","",SDK_RenderDigit("Auto",_xlpm.note,_xlpm.cand,1)),_xlfn.TEXTJOIN(" ",TRUE,_xlpm.mark,_xlpm.digit))} | O13: {=IF(_Engine!E6<>"","",SDK_RenderDigit("Auto",$Q$15,_Engine!E18,2))} | P13: {=IF(_Engine!E6<>"","",SDK_RenderDigit("Auto",$Q$15,_Engine!E18,3))} | R13: {=_xlfn.LET(_xlpm.r,QUOTIENT(ROW()-4,3)+1,_xlpm.c,QUOTIENT(COLUMN()-2,4)+1,_xlpm.live,INDEX(_Engine!$B$3:$J$11,_xlpm.r,_xlpm.c),_xlpm.cand,INDEX(_Engine!$B$15:$J$23,_xlpm.r,_xlpm.c),_xlpm.bad,INDEX(_Engine!$B$51:$J$59,_xlpm.r,_xlpm.c),_xlpm.note,INDEX($B$4:$AK$30,3*_xlpm.r,4*_xlpm.c),_xlpm.coord,"R"&_xlpm.r&"C"&_xlpm.c,_xlpm.role,SDK_CoordRole(_Engine!$B$88,_xlpm.coord),_xlpm.mark,IF(_xlpm.bad,"✖",IF($AS$11="Off","",IF(_xlpm.role="TARGET","▼",IF(_xlpm.role="SOURCE","●","")))),_xlpm.digit,IF(_xlpm.live<>"","",SDK_RenderDigit("Auto",_xlpm.note,_xlpm.cand,1)),_xlfn.TEXTJOIN(" ",TRUE,_xlpm.mark,_xlpm.digit))} | S13: {=IF(_Engine!F6<>"","",SDK_RenderDigit("Auto",$U$15,_Engine!F18,2))} | T13: {=IF(_Engine!F6<>"","",SDK_RenderDigit("Auto",$U$15,_Engine!F18,3))} | V13: {=_xlfn.LET(_xlpm.r,QUOTIENT(ROW()-4,3)+1,_xlpm.c,QUOTIENT(COLUMN()-2,4)+1,_xlpm.live,INDEX(_Engine!$B$3:$J$11,_xlpm.r,_xlpm.c),_xlpm.cand,INDEX(_Engine!$B$15:$J$23,_xlpm.r,_xlpm.c),_xlpm.bad,INDEX(_Engine!$B$51:$J$59,_xlpm.r,_xlpm.c),_xlpm.note,INDEX($B$4:$AK$30,3*_xlpm.r,4*_xlpm.c),_xlpm.coord,"R"&_xlpm.r&"C"&_xlpm.c,_xlpm.role,SDK_CoordRole(_Engine!$B$88,_xlpm.coord),_xlpm.mark,IF(_xlpm.bad,"✖",IF($AS$11="Off","",IF(_xlpm.role="TARGET","▼",IF(_xlpm.role="SOURCE","●","")))),_xlpm.digit,IF(_xlpm.live<>"","",SDK_RenderDigit("Auto",_xlpm.note,_xlpm.cand,1)),_xlfn.TEXTJOIN(" ",TRUE,_xlpm.mark,_xlpm.digit))} -> 1 | W13: {=IF(_Engine!G6<>"","",SDK_RenderDigit("Auto",$Y$15,_Engine!G18,2))} | X13: {=IF(_Engine!G6<>"","",SDK_RenderDigit("Auto",$Y$15,_Engine!G18,3))} | Z13: {=_xlfn.LET(_xlpm.r,QUOTIENT(ROW()-4,3)+1,_xlpm.c,QUOTIENT(COLUMN()-2,4)+1,_xlpm.live,INDEX(_Engine!$B$3:$J$11,_xlpm.r,_xlpm.c),_xlpm.cand,INDEX(_Engine!$B$15:$J$23,_xlpm.r,_xlpm.c),_xlpm.bad,INDEX(_Engine!$B$51:$J$59,_xlpm.r,_xlpm.c),_xlpm.note,INDEX($B$4:$AK$30,3*_xlpm.r,4*_xlpm.c),_xlpm.coord,"R"&_xlpm.r&"C"&_xlpm.c,_xlpm.role,SDK_CoordRole(_Engine!$B$88,_xlpm.coord),_xlpm.mark,IF(_xlpm.bad,"✖",IF($AS$11="Off","",IF(_xlpm.role="TARGET","▼",IF(_xlpm.role="SOURCE","●","")))),_xlpm.digit,IF(_xlpm.live<>"","",SDK_RenderDigit("Auto",_xlpm.note,_xlpm.cand,1)),_xlfn.TEXTJOIN(" ",TRUE,_xlpm.mark,_xlpm.digit))} | AA13: {=IF(_Engine!H6<>"","",SDK_RenderDigit("Auto",$AC$15,_Engine!H18,2))} | AB13: {=IF(_Engine!H6<>"","",SDK_RenderDigit("Auto",$AC$15,_Engine!H18,3))} | AD13: {=_xlfn.LET(_xlpm.r,QUOTIENT(ROW()-4,3)+1,_xlpm.c,QUOTIENT(COLUMN()-2,4)+1,_xlpm.live,INDEX(_Engine!$B$3:$J$11,_xlpm.r,_xlpm.c),_xlpm.cand,INDEX(_Engine!$B$15:$J$23,_xlpm.r,_xlpm.c),_xlpm.bad,INDEX(_Engine!$B$51:$J$59,_xlpm.r,_xlpm.c),_xlpm.note,INDEX($B$4:$AK$30,3*_xlpm.r,4*_xlpm.c),_xlpm.coord,"R"&_xlpm.r&"C"&_xlpm.c,_xlpm.role,SDK_CoordRole(_Engine!$B$88,_xlpm.coord),_xlpm.mark,IF(_xlpm.bad,"✖",IF($AS$11="Off","",IF(_xlpm.role="TARGET","▼",IF(_xlpm.role="SOURCE","●","")))),_xlpm.digit,IF(_xlpm.live<>"","",SDK_RenderDigit("Auto",_xlpm.note,_xlpm.cand,1)),_xlfn.TEXTJOIN(" ",TRUE,_xlpm.mark,_xlpm.digit))} | AE13: {=IF(_Engine!I6<>"","",SDK_RenderDigit("Auto",$AG$15,_Engine!I18,2))} -> 2 | AF13: {=IF(_Engine!I6<>"","",SDK_RenderDigit("Auto",$AG$15,_Engine!I18,3))} | AH13: {=_xlfn.LET(_xlpm.r,QUOTIENT(ROW()-4,3)+1,_xlpm.c,QUOTIENT(COLUMN()-2,4)+1,_xlpm.live,INDEX(_Engine!$B$3:$J$11,_xlpm.r,_xlpm.c),_xlpm.cand,INDEX(_Engine!$B$15:$J$23,_xlpm.r,_xlpm.c),_xlpm.bad,INDEX(_Engine!$B$51:$J$59,_xlpm.r,_xlpm.c),_xlpm.note,INDEX($B$4:$AK$30,3*_xlpm.r,4*_xlpm.c),_xlpm.coord,"R"&_xlpm.r&"C"&_xlpm.c,_xlpm.role,SDK_CoordRole(_Engine!$B$88,_xlpm.coord),_xlpm.mark,IF(_xlpm.bad,"✖",IF($AS$11="Off","",IF(_xlpm.role="TARGET","▼",IF(_xlpm.role="SOURCE","●","")))),_xlpm.digit,IF(_xlpm.live<>"","",SDK_RenderDigit("Auto",_xlpm.note,_xlpm.cand,1)),_xlfn.TEXTJOIN(" ",TRUE,_xlpm.mark,_xlpm.digit))} | AI13: {=IF(_Engine!J6<>"","",SDK_RenderDigit("Auto",$AK$15,_Engine!J18,2))} | AJ13: {=IF(_Engine!J6<>"","",SDK_RenderDigit("Auto",$AK$15,_Engine!J18,3))}
B14: {=_xlfn.LET(_xlpm.r,QUOTIENT(ROW()-5,3)+1,_xlpm.c,QUOTIENT(COLUMN()-2,4)+1,_xlpm.live,INDEX(_Engine!$B$3:$J$11,_xlpm.r,_xlpm.c),_xlpm.cand,INDEX(_Engine!$B$15:$J$23,_xlpm.r,_xlpm.c),_xlpm.note,INDEX($B$4:$AK$30,3*_xlpm.r,4*_xlpm.c),IF(_xlpm.live<>"","",_xlfn.TEXTJOIN("·",TRUE,SDK_RenderDigit("Auto",_xlpm.note,_xlpm.cand,4),SDK_RenderDigit("Auto",_xlpm.note,_xlpm.cand,5))))} | C14: =_Engine!B30 -> 8 | D14: {=IF(_Engine!B6<>"","",SDK_RenderDigit("Auto",$E$15,_Engine!B18,6))} | F14: {=_xlfn.LET(_xlpm.r,QUOTIENT(ROW()-5,3)+1,_xlpm.c,QUOTIENT(COLUMN()-2,4)+1,_xlpm.live,INDEX(_Engine!$B$3:$J$11,_xlpm.r,_xlpm.c),_xlpm.cand,INDEX(_Engine!$B$15:$J$23,_xlpm.r,_xlpm.c),_xlpm.note,INDEX($B$4:$AK$30,3*_xlpm.r,4*_xlpm.c),IF(_xlpm.live<>"","",_xlfn.TEXTJOIN("·",TRUE,SDK_RenderDigit("Auto",_xlpm.note,_xlpm.cand,4),SDK_RenderDigit("Auto",_xlpm.note,_xlpm.cand,5))))} -> 5 | H14: {=IF(_Engine!C6<>"","",SDK_RenderDigit("Auto",$I$15,_Engine!C18,6))} | J14: {=_xlfn.LET(_xlpm.r,QUOTIENT(ROW()-5,3)+1,_xlpm.c,QUOTIENT(COLUMN()-2,4)+1,_xlpm.live,INDEX(_Engine!$B$3:$J$11,_xlpm.r,_xlpm.c),_xlpm.cand,INDEX(_Engine!$B$15:$J$23,_xlpm.r,_xlpm.c),_xlpm.note,INDEX($B$4:$AK$30,3*_xlpm.r,4*_xlpm.c),IF(_xlpm.live<>"","",_xlfn.TEXTJOIN("·",TRUE,SDK_RenderDigit("Auto",_xlpm.note,_xlpm.cand,4),SDK_RenderDigit("Auto",_xlpm.note,_xlpm.cand,5))))} -> 5 | L14: {=IF(_Engine!D6<>"","",SDK_RenderDigit("Auto",$M$15,_Engine!D18,6))} | N14: {=_xlfn.LET(_xlpm.r,QUOTIENT(ROW()-5,3)+1,_xlpm.c,QUOTIENT(COLUMN()-2,4)+1,_xlpm.live,INDEX(_Engine!$B$3:$J$11,_xlpm.r,_xlpm.c),_xlpm.cand,INDEX(_Engine!$B$15:$J$23,_xlpm.r,_xlpm.c),_xlpm.note,INDEX($B$4:$AK$30,3*_xlpm.r,4*_xlpm.c),IF(_xlpm.live<>"","",_xlfn.TEXTJOIN("·",TRUE,SDK_RenderDigit("Auto",_xlpm.note,_xlpm.cand,4),SDK_RenderDigit("Auto",_xlpm.note,_xlpm.cand,5))))} -> 5 | P14: {=IF(_Engine!E6<>"","",SDK_RenderDigit("Auto",$Q$15,_Engine!E18,6))} | R14: {=_xlfn.LET(_xlpm.r,QUOTIENT(ROW()-5,3)+1,_xlpm.c,QUOTIENT(COLUMN()-2,4)+1,_xlpm.live,INDEX(_Engine!$B$3:$J$11,_xlpm.r,_xlpm.c),_xlpm.cand,INDEX(_Engine!$B$15:$J$23,_xlpm.r,_xlpm.c),_xlpm.note,INDEX($B$4:$AK$30,3*_xlpm.r,4*_xlpm.c),IF(_xlpm.live<>"","",_xlfn.TEXTJOIN("·",TRUE,SDK_RenderDigit("Auto",_xlpm.note,_xlpm.cand,4),SDK_RenderDigit("Auto",_xlpm.note,_xlpm.cand,5))))} | S14: =_Engine!F30 -> 6 | T14: {=IF(_Engine!F6<>"","",SDK_RenderDigit("Auto",$U$15,_Engine!F18,6))} | V14: {=_xlfn.LET(_xlpm.r,QUOTIENT(ROW()-5,3)+1,_xlpm.c,QUOTIENT(COLUMN()-2,4)+1,_xlpm.live,INDEX(_Engine!$B$3:$J$11,_xlpm.r,_xlpm.c),_xlpm.cand,INDEX(_Engine!$B$15:$J$23,_xlpm.r,_xlpm.c),_xlpm.note,INDEX($B$4:$AK$30,3*_xlpm.r,4*_xlpm.c),IF(_xlpm.live<>"","",_xlfn.TEXTJOIN("·",TRUE,SDK_RenderDigit("Auto",_xlpm.note,_xlpm.cand,4),SDK_RenderDigit("Auto",_xlpm.note,_xlpm.cand,5))))} -> 4 | X14: {=IF(_Engine!G6<>"","",SDK_RenderDigit("Auto",$Y$15,_Engine!G18,6))} | Z14: {=_xlfn.LET(_xlpm.r,QUOTIENT(ROW()-5,3)+1,_xlpm.c,QUOTIENT(COLUMN()-2,4)+1,_xlpm.live,INDEX(_Engine!$B$3:$J$11,_xlpm.r,_xlpm.c),_xlpm.cand,INDEX(_Engine!$B$15:$J$23,_xlpm.r,_xlpm.c),_xlpm.note,INDEX($B$4:$AK$30,3*_xlpm.r,4*_xlpm.c),IF(_xlpm.live<>"","",_xlfn.TEXTJOIN("·",TRUE,SDK_RenderDigit("Auto",_xlpm.note,_xlpm.cand,4),SDK_RenderDigit("Auto",_xlpm.note,_xlpm.cand,5))))} -> 4·5 | AB14: {=IF(_Engine!H6<>"","",SDK_RenderDigit("Auto",$AC$15,_Engine!H18,6))} | AD14: {=_xlfn.LET(_xlpm.r,QUOTIENT(ROW()-5,3)+1,_xlpm.c,QUOTIENT(COLUMN()-2,4)+1,_xlpm.live,INDEX(_Engine!$B$3:$J$11,_xlpm.r,_xlpm.c),_xlpm.cand,INDEX(_Engine!$B$15:$J$23,_xlpm.r,_xlpm.c),_xlpm.note,INDEX($B$4:$AK$30,3*_xlpm.r,4*_xlpm.c),IF(_xlpm.live<>"","",_xlfn.TEXTJOIN("·",TRUE,SDK_RenderDigit("Auto",_xlpm.note,_xlpm.cand,4),SDK_RenderDigit("Auto",_xlpm.note,_xlpm.cand,5))))} -> 4·5 | AF14: {=IF(_Engine!I6<>"","",SDK_RenderDigit("Auto",$AG$15,_Engine!I18,6))} | AH14: {=_xlfn.LET(_xlpm.r,QUOTIENT(ROW()-5,3)+1,_xlpm.c,QUOTIENT(COLUMN()-2,4)+1,_xlpm.live,INDEX(_Engine!$B$3:$J$11,_xlpm.r,_xlpm.c),_xlpm.cand,INDEX(_Engine!$B$15:$J$23,_xlpm.r,_xlpm.c),_xlpm.note,INDEX($B$4:$AK$30,3*_xlpm.r,4*_xlpm.c),IF(_xlpm.live<>"","",_xlfn.TEXTJOIN("·",TRUE,SDK_RenderDigit("Auto",_xlpm.note,_xlpm.cand,4),SDK_RenderDigit("Auto",_xlpm.note,_xlpm.cand,5))))} | AI14: =_Engine!J30 -> 3 | AJ14: {=IF(_Engine!J6<>"","",SDK_RenderDigit("Auto",$AK$15,_Engine!J18,6))}
